Workbook
Name _: #REF!
Name _: #REF!
Name _: #REF!
Name _: #REF!
Name _: #REF!
Name _: #REF!
Name _: #REF!
Name _: #REF!
Name _: #REF!
Name _: #REF!
Name _: #REF!
Name _: #REF!
Name _: #REF!
Name _?: #N/A
Name _?쨲?f: #REF!
Name _?쨲?f: #REF!
Name _?쨲?f: #REF!
Name _?쨲?f: #REF!
Name _?쨲?f: #REF!
Name _?쨲?f: #REF!
Name _?쨲?f: #REF!
Name _?쨲?f: #REF!
Name _?쨲?f: #REF!
Name _?쨲?f: #REF!
Name _?쨲?f: #REF!
Name _?쨲?f: #REF!
Name _?쨲?f: #REF!
Name __?: #REF!
Name __?: #REF!
Name __?: #REF!
Name __?: #REF!
Name __?: #REF!
Name __?: #REF!
Name __?: #REF!
Name __?: #REF!
Name __?: #REF!
Name __?: #REF!
Name __?: #REF!
Name __?: #REF!
Name __?: #REF!
Name __?쨲?f: #REF!
Name __?쨲?f: #REF!
Name __?쨲?f: #REF!
Name __?쨲?f: #REF!
Name __?쨲?f: #REF!
Name __?쨲?f: #REF!
Name __?쨲?f: #REF!
Name __?쨲?f: #REF!
Name __?쨲?f: #REF!
Name __?쨲?f: #REF!
Name __?쨲?f: #REF!
Name __?쨲?f: #REF!
Name __?쨲?f: #REF!
Name ___?: #REF!
Name ___?: #REF!
Name ___?: #REF!
Name ___?: #REF!
Name ___?: #REF!
Name ___?: #REF!
Name ___?: #REF!

Sheet 개정이력
B1: 통합 WPC 체크시트 수정 내역
B3: Ver. | C3: 날짜 | D3: 작성자 | E3: 수정부분 | F3: 수정내용 | G3: 비 고
B4: 1.0 | C4: 17.12.01 | D4: 장문혁 | E4: - All | F4: - 최초 WPC 체크시트 작성
B5: 1.1 | C5: 18.07.09 | D5: 장문혁 | E5: - 무선충전 시스템 통합 사양서_R14_20180709_수정2 반영 (DN8 WPC M/car 대응용 사양서) | F5: 1. WPC & NFC Mode Control 1) C_IAU Option 신호 처리에 대한 항목 추가 (M/car 미반영) 2) NFC Mode에 대한 Time Out 확인 항목 추가 3) C_WPCNFCcmd 신호 값 변경 ( 0x0 : None, 0x1 : Searching On(HCE), 0x2 : Searching Off, 0x3 : Searching On(USIM)) 4) 기능 항목 수 61개 -> 174개로 변경 2. Prevention of SMK LF 1) WPCStatus != WPCMode에 대한 SMK 간섭 해제 항목 추가 2) 기능 항목 수 60개 -> 78개로 변경 3. WPC Leaving Phone 1) 기능 항목수 143개 -> 129개로 변경 (중복항목 삭제) 4. USM Setting 1) C_ProfileIDRValue 신호 수신에 따른 항목 추가 2) 기능 항목수 21개 -> 64개로 변경 5. FAN Control 항목 작성 1) 기능 항목수 12개
B6: 1.2 | C6: 18.08.21 | D6: 장문혁 | E6: - 무선충전 시스템 통합 사양서_R14_20180820_수정4반영 (DN8 WPC P1 대응용 사양서) | F6: 1. IGN 판단 전압값 변경 1) IGN On/Off : 7.8v/7.1v -> 7v/4v 2. C_IAUOption 신호 미처리 3. FAN 작동 사양 변경 1)WPC Mode & IGN1 On -> 충전 or 완충상태
B7: 1.3 | C7: 18.10.16 | D7: 장문혁 | E7: - WPC_System_Requirement_v0.8_181004.docx 반영 (DN8 WPC P2 대응용 사양서) - SCR 반영 (1) SCR-180719-003_WPC_WPC 모드 제어사양 오류 수정 _1_180720 (2) SCR-180719-004_WPC_FAN 제어로직 수정_충전중에만 FAN 동작_1_20180720 (3) SCR-180719-007_WPC_WPC&NFC 모드 변경 정합성 결과 반 영_1_20180723 (4) SCR-180719-008_WPC_카드 detection 기능 수정 _1_20180724 (5) SCR-180719-009_WPC_과전류 감지 사양 수정_1_20180724 (6) SCR-180622-003_AVN에 의한 프로필 정보 판단 로직 추가 | F7: 1. SCR-180719-003_WPC_WPC 모드 제어사양 오류 수정_1_180720 1) Function_WPCWarning 내 b_WPCSWOption 조건 추가 USM 설정에서 WPC Mode 해제 시, 방치 알림 기능은 동작되면 안되므로 b_WPCSWOption == Off 조건 추가 2) C_IGNSW 조건 수정 C_IGNSW == St 조건은 LP(5W) 사양일 때만 고려, MP(10W), MP+NFC 사양 경우 고려하지 않음 3) 불필요 신호 삭제: b_DeviceFault 2. SCR-180719-004_WPC_FAN 제어로직 수정_충전중에만 FAN 동작_1_20180720 1) FAN_Off 에서 FAN_On 으로 천이 조건 WPCStatus = WPCMode -> WPCStatus== WPCMode && b_WPCPhoneExist ==On 2) FAN_On 에서 FAN_Off 으로 천이 조건 WPCStatus != WPCMode -> WPCStatus != WPCMode || b_WPCPhoneExist == Off 3. SCR-180719-007_WPC_WPC&NFC 모드 변경 정합성 결과 반영_1_20180723 1) Function_NFCCardDetection 삭제 (WPC Mode Status Control 내 수행) 4. SCR-180719-008_WPC_카드 detection 기능 수정_1_20180724 1) Function_NFCCardDetection 동작 기존 WPC&NFC Mode Control Function 내 기능 ->WPC Mode Status Control 내 기능으로 변경 WPC Mode 진입 시, Pad 위 물체를 감지하여 충전 가능 여부 판단 핸드폰 또는 카드가 여러 개일 경우, 충전 불가 5. SCR-180719-009_WPC_과전류 감지 사양 수정_1_20180724 1) b_CurrentErrorFlag 삭제 기존 로직에서 과전류 검출 시, b_CurrentErrorFlag = On 으로 WPCMode_Run 상태에 머물고 있어 Ping이 계속됨. -> 과전류 검출마다 WPCMode_Stop 으로 천이해야 하므로, 과전류 검출 시 b_CurrentFault = On 되도록 로직 수정 과전류 10회 검출 -> 충전 금지 -> ACC 또는 IGN1이 Off에서 On으로 변경되어야 충전 금지 해제 6. SCR-180622-003_AVN에 의한 프로필 정보 판단 로직 추가 1) IAU 적용/미적용에 따른 USM 개인화 서비스 ID 변경 방식 변경 2) IAU 적용 사양 - IAU로부터 C_ProfileIDRValue 수신하여 ID 설정 대응 - 단, IAU 송신 시그널 C_ProfileIDRValue이 0x01/0x02/0x03이 아닐 경우 AVN송신 C_AVN_ProfileIDRValue값에 따라 ID 설정 3) IAU 미적용 사양 - IAU 미적용에 따라 ICU는 IAU로부터 IDRValue는 CAN Timeout 상태가 되며, AVN USM에 의한 ID 변경만 가능하므로, AVN송신 C_AVN_ProfileIDRValue값에 따라 ID 설정 4) IAU,AVN 모두 타임아웃 또는 0x01/0x02/0x03이 아닐 경우 LAST PROFILE 기준 설정값 (OLD VALUE)으로 동작 5) IAU와 AVN에서 모두 시그널이 수신될 경우 IAU 우선하여 PROFILE 설정
B9: 1.4 | C9: 18.11.12 | D9: 장문혁 | E9: - WPC_System_Requirement_v1.1_181018 반영 | F9: 1. b_IGNUseOption, b_BatteryPowerOption 반영 2. 최초 전원 인가 시 AMBER LED 3초간 점등 | G9: PY차종 전용사양 추가
B10: 1.5 | C10: 18.12.03 | D10: 장문혁 | E10: - WPC_System_Requirement_v1.3_181213 반영 | F10: 1. FAN 동작 사양 변경 기존타입 : 30% DUTY -> 50%,70% 변경시 차속만 참조 변경타입 : 30% DUTY -> 50%,70% 변경시 차속 & 온도 & 엔진 상태 참조
B11: 1.6 | C11: 19.01.21 | D11: 장문혁 | E11: - WPC_System_Requirement_v1.7_190104 반영 | F11: 1. FAN 사양 변경 1) FAN Control Function Parameter (Par_FANValueLow) 값 변경: 30% -> 20% 2) FAN_On 내부 State에서 다른 State 천이 시의 온도 조건 삭제 2. SCR-181212-015_WPC_실내 조명 사양 변경에 따른 무선충전 인디케이터 LED 제어 사양 변경 요청 1) C_DetentOut 삭제 -> IBU에서 송출하는 C_IntTailOn 신호 참조하여 인디케이터 주/야간 판단 2) 주간: IntTailOn : Rheostat 적용 차종은 설정 밝기로 출력, 미적용 차종은 25%밝기로 출력 야간: IntTtailOff : 최대 밝기로 출력
B12: 1.7 | C12: 19.01.29 | D12: 장문혁 | E12: - WPC_System_Requirement_v2.0_R2_190129 반영 | F12: 1. SCR-181212-012_WPC_C_WPC_Status 신호 삭제_1_20181218 1) 출력 신호 C_WPC_Status: IAU 에서 해당 신호 미사용 -> 불필요에 따른 삭제 2. SCR-181212-002_WPC_10W 과전류 판단값 변경_1_20181218 1) 10W의 경우도 5W와 동일하게 4500mA으로 변경 (QI 인증에 사용되는 15W 부하로 인증 진행 시 4A 이상이 되어 충전 끊김 발생 (QI 인증 불가)) 3. SCR-181212-016_WPC_FAN 제어 판단 조건 추가_분석자료_20190104 1) FANOn_Medium -> FANOn_High 천이 시, C_EngineState 조건 삭제 2) duty 50% 또는 duty 70% 로 동작 중, 엔진 상태가 Stalled, Auto Stopping, Fault인 경우에도 FAN 속도 유지
B13: 1.8 | C13: 19.05.16 | D13: 장문혁 | E13: - WPC_System_Requirement_v2.6_R1_190516 반영 | F13: 1. YG PE 전용 LED Out 로직으로 인한 State chart 변경 1) 내용 : YG PE는 주야간을 구분하는 BCM의 C_IntTailOn과 CLU의 C_DetentOut을 OR 조건으로 주야간을 구분함. 2) 근거: 고객 요청(이재혁연구원) 3) 변경내용: Option 파라메터 추가, C_IntTailOn과 C_DetentOut 조건 추가
B14: 1.9 | C14: 19.05.29 | D14: 장문혁 | E14: - WPC_System_Requirement_v2.7_R1_190527 반영 | F14: 1. 휠리모콘을 이용한 USM setting 기능 CAN 신호 추가. 1) WPC 수신 신호 비교: CLU_05_00ms, CLU_09_00ms 메시지/ 신호추가 2) WPC USM Setting Control Function State Chart 내의 휠리모콘 신호 조건 추가 (USM_StaRst1Req, USM_WpcSetReq) 2. 조명제어에 대한 CAN 신호 변경 1) 내용: 3세대 CAN은 IntTailOn에서 DetentOut 조건으로 변경. 2) 근거: 자동차 담당자 요청 | G14: 3세대 CAN 적용 차종 : RG3, JX1, MQ4
B15: 2.0 | C15: 19.07.09 | D15: 장문혁 | E15: - WPC_System_Requirement_v2.9_190703.docx 반영 | F15: 1. 개인화 프로필 USM State Chart 내용 추가 1) 각 Profile 설정값에 즉시 천이를 위해 각 State Chart 에 Profile 조건 명시 -> B+ 리셋 시 Guest로 진입후 각 프로필 진입에서 즉시 각 프로필로 진입하도록 수정됨 2. Over Temperature Detecting Function State Chart 수정 1) 과열 상태에서 정상 상태 체크로 천이 시, 온도 입력 값이 65도 이하로 수정 (정상 체크 ->과열 재진입, 65도 초과로 수정)
B16: 2.1 | C16: 19.09.27 | D16: 장문혁 | E16: - WPC_System_Requirement_v3.2_190925.docx 반영 | F16: 1. CAN 3세대 하이브리드 엔진 상태 신호에 대한 FAN Control State Chart 추가 - 신호 : HEV_EngOpSta - Engine Running 판단 값: 0x2, 0x3, 0x4, 0x5 (0x2: IS(Idle speed), 0x3: PL(Part Load), 0x4: PU(Pull), 0x5: PUC(Fuel Cut Off))
B17: 2.2 | C17: 20.03.02 | D17: 장문혁 | E17: - JX1 WPC 필드 문제점_NFC 출력 불량 반영 | F17: 1. NFC Init 로직 수정 - Wakeup 시 00h, 01h, 02h 레지스터 Defalut Value Write
B18: 2.3 | C18: 21.10.18 | D18: 장문혁 | E18: - MQ4a 무선 충전기 작동 불량 개선 위한 DUTY 값 변경 반영 | F18: 1. FAN Duty 추가 - 20/50/70/90 (0~10KPH, 엔진 정지 / 11~55KPH / 56~100KPH / 100KPH이상~) | G18: 기아사업부장님 지시사항_MQ4 차종
B19: 2.4 | C19: 22.03.05 | D19: 장문혁 | E19: - SCR-211126-004_[WPC] 무선충전기 고온 에러 표시 사양 변경 _r1_211216.pptx" 적용 | F19: 1. 무선충전기 고온 에러 표시 사양 변경 - [기존] WPC MODE시 휴대폰 거치 유/무에 상관 없이 과열 감지 및 경고 출력 → [신규 추가] 휴대폰 거치 시 에만 과열 감지 및 경고 출력 하도록 로직 변경
B20: 2.5 | C20: 22.10.19 | D20: 김장현 | E20: - SCR-210706-003_[WPC] 신규 실내 조명 제어 사양 추가 건_r1_210818 | F20: 1. 조명 제어 시(주야간 판단), 참조 CAN 신호 변경 [기존] Detent 와 레오스탯 적용 유무에 따라 DetentOut / RheostatLevel / IntTailOn 신호를 조합 판단 → [신규 추가] Detent 와 레오스탯 유무 무관, AutoBright 신호로만 판단
B21: 2.6 | C21: 22.10.19 | D21: 김장현 | E21: 타차종문제점 적용 | F21: 시동파형 B+ 전압 4V 이하 하강 반복 후 정상전압 복귀 시 유효한 HPV CAN Msg 값 송신하지 않고 초기값 0x0 값 유지되어 DTC 출력됨.
B22: 2.7 | C22: 22.11.10 | D22: 김장현 | E22: TSCR-285_[WPC] LPCD 사양 수정 (디지털키 등록 조건 추가 외)_r5_220922 | F22: 2) 디지털키 등록시 IG ON 상태에서 LPCD 미동작하도록 사양 변경 - IG ON 시 디지털키 등록을 위해 LPCD 동작함 디지털키 등록 완료 상태일 경우 LPCD 기능 불필요하여, 바로 무선충전 진입하도록 사양 변경
B23: 2.8 | C23: 24.11.01 | D23: 김장현 | E23: Non NFC 방치알림 중 도어오픈시 방치알림 중단
B24: 2.9 | C24: 24.11.04 | D24: 김장현 | E24: USM Setting Profile 9개 추가
B25: 3.0 | C25: 25.01.09 | D25: 김장현 | E25: Non NFC 방치알림 중 Drv/Ast 오픈시 방치알림 6초 후 중단 | F25: Cellphone on the pad신호를 60초 출력 중 Door(Driver || Passenger) Open 발생 시, 0x1: Cellphone on the pad 6s동안 추가로 출력 후 OFF를 송신해야 한다. | G25: 실차 클러스트 방치알림 표출 안됨으로 모베이스 자체 수정
B26: 3.1 | C26: 25.01.20 | D26: 김장현 | E26: USM_ValCmdStatforAST 신호 및 기능 추가 | F26: ATS 제어기에서 RWPC Option 설정 신호 추가
B27: 3.2 | C27: 25.02.18 | D27: 김장현 | E27: DIAGNOSTIC T/C 통합 과거차 문제점 반영
B28: 3.3 | C28: 25.07.04 | D28: 김장현 | E28: T/C 추적성 연결
B29: 3.4 | C29: 25.08.01 | D29: 김장현 | E29: JG 전원체계 (방치알림 반영) 23차 사양 반영

Sheet 평가항목
B1: ■ Check Items / Results
B3: No | C3: Function | D3: 항목수 | E3: TEST | J3: REMARK
E4: 검사항목 | F4: OK 항목 | G4: NG 항목 | H4: N/A | I4: 완료율(%)
B5: 1 | C5: SLEEP & WAKE UP | D5: =F5+G5+H5 -> 70 | E5: =F5+G5 -> 69 | F5: =SUM('Sleep & Wake Up'!$AD$9) -> 69 | G5: =SUM('Sleep & Wake Up'!$AD$10) -> 0 | H5: =SUM('Sleep & Wake Up'!$AD$11) -> 1 | I5: =F5/E5% -> 100 | J5: - RWPC 사양 N/A처리 | L5: - NFC WPC 사양 N/A 처리
B6: 2 | C6: Power Off Control | D6: =F6+G6+H6 -> 25 | E6: =F6+G6 -> 25 | F6: =SUM('Power Off Control'!$AC$6) -> 25 | G6: =SUM('Power Off Control'!$AC$11) -> 0 | H6: =SUM('Power Off Control'!$AC$16) -> 0 | I6: =F6/E6% -> 100
B7: 3 | C7: WPC & NFC Mode | D7: =F7+G7+H7 -> 288 | E7: =F7+G7 -> 232 | F7: =SUM('WPC & NFC Mode Control'!$AL$7) -> 232 | G7: =SUM('WPC & NFC Mode Control'!$AL$8) -> 0 | H7: =SUM('WPC & NFC Mode Control'!$AL$9) -> 56 | I7: =F7/E7% -> 100 | J7: - Non NFC 적용 사양 N/A 처리 - PY F/L 전용 사양 N/A 처리 | L7: - PY F/L 전용 사양 N/A 처리
B8: 4 | C8: WPC Power | D8: =F8+G8+H8 -> 46 | E8: =F8+G8 -> 46 | F8: =SUM('Over Voltage & Under Voltage'!$AB$9) -> 46 | G8: =SUM('Over Voltage & Under Voltage'!$AB$10) -> 0 | H8: =SUM('Over Voltage & Under Voltage'!$AB$11) -> 0 | I8: =F8/E8% -> 100
B9: 5 | C9: Prevention of SMK LF | D9: =F9+G9+H9 -> 122 | E9: =F9+G9 -> 122 | F9: =SUM('Prevention of SMK LF'!$AF$10) -> 122 | G9: =SUM('Prevention of SMK LF'!$AF$11) -> 0 | H9: =SUM('Prevention of SMK LF'!$AF$12) -> 0 | I9: =F9/E9% -> 100
B10: 6 | C10: Over Current Detecting | D10: =F10+G10+H10 -> 7 | E10: =F10+G10 -> 7 | F10: =SUM('Over Current Detecting'!$AB$8) -> 7 | G10: =SUM('Over Current Detecting'!$AB$9) -> 0 | H10: =SUM('Over Current Detecting'!$AB$9) -> 0 | I10: =F10/E10% -> 100
B11: 7 | C11: Over Voltage & Under Voltage | D11: =F11+G11+H11 -> 46 | E11: =F11+G11 -> 46 | F11: =SUM('Over Voltage & Under Voltage'!$AB$9) -> 46 | G11: =SUM('Over Voltage & Under Voltage'!$AB$10) -> 0 | H11: =SUM('Over Voltage & Under Voltage'!$AB$11) -> 0 | I11: =F11/E11% -> 100
B12: 8 | C12: WPC Leaving Phone | D12: =F12+G12+H12 -> 156 | E12: =F12+G12 -> 32 | F12: =SUM('WPC Leaving Phone'!$AL$8) -> 32 | G12: =SUM('WPC Leaving Phone'!$AL$9) -> 0 | H12: =SUM('WPC Leaving Phone'!$AL$10) -> 124 | I12: =F12/E12% -> 100 | J12: - Drv/AST 오픈시 1분 유지 상양 N/A처리
B13: 9 | C13: Temperature Sensor Error | D13: =F13+G13+H13 -> 30 | E13: =F13+G13 -> 8 | F13: =SUM('Temperature Sensor Error'!$AB$9) -> 8 | G13: =SUM('Temperature Sensor Error'!$AB$10) -> 0 | H13: =SUM('Temperature Sensor Error'!$AB$11) -> 22 | I13: =F13/E13% -> 100 | J13: - 3Coil 사양 N/A처리
B14: 10 | C14: LED Output | D14: =F14+G14+H14 -> 114 | E14: =F14+G14 -> 18 | F14: =SUM('LED Output Control'!$AC$6) -> 18 | G14: =SUM('LED Output Control'!$AC$7) -> 0 | H14: =SUM('LED Output Control'!$AC$8) -> 96 | I14: =F14/E14% -> 100 | J14: - Rhoestat 적용 사양, Detent Out 적용사양, PY차종 및 YGPE 차종 사양 N/A 처리 | L14: - Rhoestat 적용 사양, Detent Out 적용사양, PY차종 및 YGPE 차종 사양 N/A 처리
B15: 11 | C15: USM Setting | D15: =F15+G15+H15 -> 683 | E15: =F15+G15 -> 671 | F15: =SUM('USM Setting'!$AG$9) -> 671 | G15: =SUM('USM Setting'!$AG$10) -> 0 | H15: =SUM('USM Setting'!$AG$11) -> 12 | I15: =F15/E15% -> 100 | J15: - IAU 미적용 사양 N/A 처리 | L15: - IAU 적용 사양 N/A 처리
B16: 12 | C16: Over Temperature Detecting | D16: =F16+G16+H16 -> 45 | E16: =F16+G16 -> 13 | F16: =SUM('Over Temperature Detecting'!$AB$10) -> 13 | G16: =SUM('Over Temperature Detecting'!$AB$11) -> 0 | H16: =SUM('Over Temperature Detecting'!$AB$12) -> 32 | I16: =F16/E16% -> 100 | J16: - 3Coil 사양 N/A처리 | L16: - NFC WPC 사양 N/A 처리
B17: 13 | C17: Phone Left Detecting Control | D17: =F17+G17+H17 -> 11 | E17: =F17+G17 -> 11 | F17: =SUM('Phone Left Detecting Control'!$AB$8) -> 11 | G17: =SUM('Phone Left Detecting Control'!$AB$9) -> 0 | H17: =SUM('Phone Left Detecting Control'!$AB$10) -> 0 | I17: 0 | J17: - 기능 미구현으로 N/A 처리
B18: 14 | C18: FOD | D18: =F18+G18+H18 -> 9 | E18: =F18+G18 -> 7 | F18: =SUM('FOD Control'!$AB$7) -> 7 | G18: =SUM('FOD Control'!$AB$8) -> 0 | H18: =SUM('FOD Control'!$AB$9) -> 2 | I18: =F18/E18% -> 100 | J18: -Ainmation 사양 N/A처리
B19: 15 | C19: FAN | D19: =F19+G19+H19 -> 265 | E19: =F19+G19 -> 28 | F19: =SUM('FAN Control'!$AD$8) -> 28 | G19: =SUM('FAN Control'!$AD$9) -> 0 | H19: =SUM('FAN Control'!$AD$10) -> 237 | I19: =F19/E19% -> 100 | J19: - FAN Duty 4단계, CAN3세대 HEV차종, PY 차종 사양 N/A 처리 | L19: - NFC WPC 사양 N/A 처리
B20: 16 | C20: DIAGNOSTIC | D20: =F20+G20+H20 -> 288 | E20: 233 | F20: 233 | G20: 8 | H20: 47 | I20: =F20/E20% -> 100 | J20: - 미적용 N/A처리
B21: 17 | C21: 과거차문제점/타차종 강건화 | D21: =F21+G21+H21 -> 64 | E21: =F21+G21 -> 64 | F21: ='과거차,타차종'!AB6 -> 64 | G21: 0 | H21: 0 | I21: =F21/E21% -> 100
B22: TOTAL | D22: =SUM(D5:D21) -> 2269 | E22: =SUM(E5:E21) -> 1632 | F22: =SUM(F5:F21) -> 1632 | G22: =SUM(G5:G20) -> 8 | H22: =SUM(H5:H21) -> 629 | I22: =F22/E22% -> 100
C25: Phone Left Detecting Control

Sheet Sleep & Wake Up
B1: 1. Sleep & Wake Up
B2: WPC(SW)-동작성능-12
B3: 1) 일반 사용자 조건
B7: No. | C7: 초기 조건 | E7: 평가 내용 | T7: Sleep 여부 | V7: 암전류 측정값 [mA] | X7: 개발목표치 | Y7: 결과 | Z7: 비고 | AD7: 항목 수
A8: WPC-기능-001~002 | B8: WPC(SW)-동작성능-12-1 | C8: 휴대폰 미거치 | E8: All Door Close 상태에서 Sleep 진입 후 암전류 측정 | T8: OK | X8: 1mA↓ | Y8: OK | AC8: 총 | AD8: =SUM(AD9:AD11) -> 70
A9: WPC-기능-001~002 | B9: WPC(SW)-동작성능-12-2 | C9: 휴대폰 미거치 | E9: Drv Door Open 상태에서 Sleep 진입 후 암전류 측정 | T9: OK | Y9: OK | AC9: OK | AD9: =COUNTIF(Y:Y,"OK") -> 69
A10: WPC-기능-001~002 | B10: WPC(SW)-동작성능-12-3 | C10: 휴대폰 미거치 | E10: Ast Door Open 상태에서 Sleep 진입 후 암전류 측정 | T10: OK | Y10: OK | AC10: NG | AD10: =COUNTIF(Y:Y,"NG") -> 0
A11: WPC-기능-001~002 | B11: WPC(SW)-동작성능-12-4 | C11: 휴대폰 미거치 | E11: RL Door Open 상태에서 Sleep 진입 후 암전류 측정 | T11: OK | Y11: OK | AC11: N/A | AD11: =COUNTIF(Y:Y,"N/A") -> 1
A12: WPC-기능-001~002 | B12: WPC(SW)-동작성능-12-5 | C12: 휴대폰 미거치 | E12: RR Door Open 상태에서 Sleep 진입 후 암전류 측정 | T12: OK | Y12: OK
A13: WPC-기능-001~002 | B13: WPC(SW)-동작성능-12-6 | C13: 휴대폰 미거치 | E13: C_WPCNFCcmd = 0x02 (NFC Searching Off) 수신하고 Sleep 진입 후 암전류 측정 | T13: OK | Y13: OK | Z13: NFC 적용사양
A14: WPC-기능-001~002 | B14: WPC(SW)-동작성능-12-7 | C14: 휴대폰 거치 | E14: All Door Close 상태에서 방치알림 종료 및 Sleep 진입 후 암전류 측정 | T14: OK | Y14: OK
A15: WPC-기능-001~002 | B15: WPC(SW)-동작성능-12-8 | C15: 휴대폰 거치 | E15: Drv Door Open 상태에서 방치알림 종료 및 Sleep 진입 후 암전류 측정 | T15: OK | Y15: OK
A16: WPC-기능-001~002 | B16: WPC(SW)-동작성능-12-9 | C16: 휴대폰 거치 | E16: Ast Door Open 상태에서 방치알림 종료 및 Sleep 진입 후 암전류 측정 | T16: OK | Y16: OK
A17: WPC-기능-001~002 | B17: WPC(SW)-동작성능-12-10 | C17: 휴대폰 거치 | E17: RL Door Open 상태에서 방치알림 종료 및 Sleep 진입 후 암전류 측정 | T17: OK | Y17: OK
A18: WPC-기능-001~002 | B18: WPC(SW)-동작성능-12-11 | C18: 휴대폰 거치 | E18: RR Door Open 상태에서 방치알림 종료 및 Sleep 진입 후 암전류 측정 | T18: OK | Y18: OK
A19: WPC-기능-001~002 | B19: WPC(SW)-동작성능-12-12 | C19: 휴대폰 거치 | E19: All Door Close 상태에서 방치알림 중간 휴대폰 제거 및 Sleep 진입 후 암전류 측정 | T19: OK | Y19: OK
A20: WPC-기능-001~002 | B20: WPC(SW)-동작성능-12-13 | C20: 휴대폰 거치 | E20: Drv Door Open 상태에서 방치알림 중간 휴대폰 제거 및 Sleep 진입 후 암전류 측정 | T20: OK | Y20: OK
A21: WPC-기능-001~002 | B21: WPC(SW)-동작성능-12-14 | C21: 휴대폰 거치 | E21: Ast Door Open 상태에서 방치알림 중간 휴대폰 제거 및 Sleep 진입 후 암전류 측정 | T21: OK | Y21: OK
A22: WPC-기능-001~002 | B22: WPC(SW)-동작성능-12-15 | C22: 휴대폰 거치 | E22: RL Door Open 상태에서 방치알림 중간 휴대폰 제거 및 Sleep 진입 후 암전류 측정 | T22: OK | Y22: OK
A23: WPC-기능-001~002 | B23: WPC(SW)-동작성능-12-16 | C23: 휴대폰 거치 | E23: RR Door Open 상태에서 방치알림 중간 휴대폰 제거 및 Sleep 진입 후 암전류 측정 | T23: OK | Y23: OK
B25: 1) 일반 사용자 조건(전기차 전원 체계 반영)
B26: No. | C26: 초기 조건 | E26: 평가 내용 | T26: Sleep 여부 | V26: 암전류 측정값 [mA] | X26: 개발목표치 | Y26: 결과 | Z26: 비고
B27: WPC(SW)-동작성능-12-1 | C27: 휴대폰 미거치 | E27: All Door Close 상태에서 Sleep 진입 후 암전류 측정 | T27: OK | X27: 1mA↓ | Y27: OK
B28: WPC(SW)-동작성능-12-2 | C28: 휴대폰 미거치 | E28: Drv Door Open → Close 상태에서 Sleep 진입 후 암전류 측정 | T28: OK | Y28: OK
B29: WPC(SW)-동작성능-12-3 | C29: 휴대폰 미거치 | E29: Ast Door Open → Close 상태에서 Sleep 진입 후 암전류 측정 | T29: OK | Y29: OK
B30: WPC(SW)-동작성능-12-4 | C30: 휴대폰 미거치 | E30: RL Door Open → Close상태에서 Sleep 진입 후 암전류 측정 | T30: OK | Y30: OK
B31: WPC(SW)-동작성능-12-5 | C31: 휴대폰 미거치 | E31: RR Door Open → Close상태에서 Sleep 진입 후 암전류 측정 | T31: OK | Y31: OK
B32: WPC(SW)-동작성능-12-6 | C32: 휴대폰 미거치 | E32: C_WPCNFCcmd = 0x02 (NFC Searching Off) 수신하고 Door Open → Close Sleep 진입 후 암전류 측정 | T32: OK | Y32: OK | Z32: NFC 적용사양
B33: WPC(SW)-동작성능-12-7 | C33: 휴대폰 거치 | E33: All Door Open → Close 상태에서 방치알림 종료 및 Sleep 진입 후 암전류 측정 | T33: OK | Y33: OK
B34: WPC(SW)-동작성능-12-8 | C34: 휴대폰 거치 | E34: Drv Door Open → Close 상태에서 방치알림 종료 및 Sleep 진입 후 암전류 측정 | T34: OK | Y34: OK
B35: WPC(SW)-동작성능-12-9 | C35: 휴대폰 거치 | E35: Ast Door Open → Close 상태에서 방치알림 종료 및 Sleep 진입 후 암전류 측정 | T35: OK | Y35: OK
B36: WPC(SW)-동작성능-12-10 | C36: 휴대폰 거치 | E36: RL Door Open → Close 상태에서 방치알림 종료 및 Sleep 진입 후 암전류 측정 | T36: OK | Y36: OK
B37: WPC(SW)-동작성능-12-11 | C37: 휴대폰 거치 | E37: RR Door Open → Close 상태에서 방치알림 종료 및 Sleep 진입 후 암전류 측정 | T37: OK | Y37: OK
B38: WPC(SW)-동작성능-12-12 | C38: 휴대폰 거치 | E38: All Door Open → Close 상태에서 방치알림 중간 휴대폰 제거 및 Sleep 진입 후 암전류 측정 | T38: OK | Y38: OK
B39: WPC(SW)-동작성능-12-13 | C39: 휴대폰 거치 | E39: Drv Door Open → Close 상태에서 방치알림 중간 휴대폰 제거 및 Sleep 진입 후 암전류 측정 | T39: OK | Y39: OK
B40: WPC(SW)-동작성능-12-14 | C40: 휴대폰 거치 | E40: Ast Door Open → Close 상태에서 방치알림 중간 휴대폰 제거 및 Sleep 진입 후 암전류 측정 | T40: OK | Y40: OK
B41: WPC(SW)-동작성능-12-15 | C41: 휴대폰 거치 | E41: RL Door Open → Close 상태에서 방치알림 중간 휴대폰 제거 및 Sleep 진입 후 암전류 측정 | T41: OK | Y41: OK
B42: WPC(SW)-동작성능-12-16 | C42: 휴대폰 거치 | E42: RR Door Open → Close 상태에서 방치알림 중간 휴대폰 제거 및 Sleep 진입 후 암전류 측정 | T42: OK | Y42: OK
B44: WPC(SW)-동작성능-2
B45: No. | C45: 구분 | E45: 평가 내용 | T45: Sleep 여부 | V45: 암전류 측정값 [mA] | X45: 개발목표치 | Y45: 결과 | Z45: 비고
...

Sheet Power Off Control
B1: Power Off Control
B3: WPC(SW)-기능-46
B4: No. | C4: 평가내용 | Y4: 결과 | Z4: 비고 | AC4: 항목 수
C5: Input | Q5: Output | AB5: 총 | AC5: =SUM(AC6:AC16) -> 25
A6: WPC-기능-007~009 | B6: WPC(SW)-기능-46-1 | C6: B+ = 9V 에서 CCU_ForcedPowerOfReq == 0x1(On in the non-sleep state) 수신 | Q6: WPC 리셋 및 Sleep 정상동작 확인 | Y6: OK | Z6: NFC 적용사양 | AB6: OK | AC6: =COUNTIF(Y:Y,"OK") -> 25
A7: WPC-기능-007~009 | B7: WPC(SW)-기능-46-1 | C7: B+ = 8.5V 에서 CCU_ForcedPowerOfReq == 0x1(On in the non-sleep state) 수신 | Q7: WPC 리셋 및 Sleep 정상동작 확인 | Y7: OK | Z7: NFC 적용사양 | AB7: NG | AC7: =COUNTIF(Y:Y,"NG") -> 0
A8: WPC-기능-007~009 | B8: WPC(SW)-기능-46-1 | C8: B+ = 8V 에서 CCU_ForcedPowerOfReq == 0x1(On in the non-sleep state) 수신 | Q8: WPC 리셋 및 Sleep 정상동작 확인 | Y8: OK | Z8: NFC 적용사양 | AB8: N/A | AC8: =COUNTIF(Y:Y,"N/A") -> 0
A9: WPC-기능-007~009 | B9: WPC(SW)-기능-46-1 | C9: B+ = 7.5V 에서 CCU_ForcedPowerOfReq == 0x1(On in the non-sleep state) 수신 | Q9: WPC 리셋 및 Sleep 정상동작 확인 | Y9: OK | Z9: NFC 적용사양
A10: WPC-기능-007~009 | B10: WPC(SW)-기능-46-1 | C10: B+ = 7V 에서 CCU_ForcedPowerOfReq == 0x1(On in the non-sleep state) 수신 | Q10: WPC 리셋 및 Sleep 정상동작 확인 | Y10: OK | Z10: NFC 적용사양
A11: WPC-기능-007~009 | B11: WPC(SW)-기능-46-2 | C11: 위 Case 이후 IGN ON시 | Q11: Wake up 정상동작 확인 | Y11: OK | Z11: NFC 적용사양
A12: WPC-기능-007~009 | B12: WPC(SW)-기능-46-2 | C12: 9V 초과 CCU_ForcedPowerOfReq == 0x1(On in the non-sleep state) 수신 | Q12: WPC 리셋 수행 되지 말것 | Y12: OK | Z12: NFC 적용사양
A13: WPC-기능-007~009 | B13: WPC(SW)-기능-46-1 | C13: 9V 이하 CCU_ForcedPowerOfReq == 0x00수신 | Q13: WPC 리셋 수행 되지 말것 | Y13: OK | Z13: NFC 적용사양
A14: WPC-기능-007~009 | B14: WPC(SW)-기능-46-1 | C14: 9V 초과 CCU_ForcedPowerOfReq == 0x00수신 | Q14: WPC 리셋 수행 되지 말것 | Y14: OK | Z14: NFC 적용사양
A15: WPC-기능-007~009 | B15: WPC(SW)-기능-46-1 | C15: CAN_PDC_ResetFuncOpt == ! Applied 상태에서 CCU_ForcedPowerOfReq == 0x1(On in the non-sleep state) 수신하여 리셋 중 PDC 리셋 수신 시 | Q15: PDC 리셋 신호 무시 할것 (CCU_ForcedPowerOfReq 리셋 정상 동작 될 것) | Y15: OK | Z15: NFC 적용사양
B16: WPC(SW)-기능-47
A17: WPC-기능-007~009 | B17: WPC(SW)-기능-47-1 | C17: B+ = 9V 에서 CAN_PDC_ResetFuncOpt == Applied IGN Off → PDC_ResetPreWrngForOthers == Warning → PDC_ResetReqForOthers ==(Reset Request) 수신 | Q17: 1.리셋 정상 동작 WPC_ResetOpSta == ResetComplete 출력 1분 출력 | Y17: OK
A18: WPC-기능-007~009 | B18: WPC(SW)-기능-47-1 | C18: B+ = 10V 에서 CAN_PDC_ResetFuncOpt == Applied IGN Off → PDC_ResetPreWrngForOthers == Warning → PDC_ResetReqForOthers ==(Reset Request) 수신 | Q18: 1.리셋 정상 동작 WPC_ResetOpSta == ResetComplete 출력 1분 출력 | Y18: OK
A19: WPC-기능-007~009 | B19: WPC(SW)-기능-47-1 | C19: B+ = 11V 에서 CAN_PDC_ResetFuncOpt == Applied IGN Off → PDC_ResetPreWrngForOthers == Warning → PDC_ResetReqForOthers ==(Reset Request) 수신 | Q19: 1.리셋 정상 동작 WPC_ResetOpSta == ResetComplete 출력 1분 출력 | Y19: OK
A20: WPC-기능-007~009 | B20: WPC(SW)-기능-47-1 | C20: B+ = 12V 에서 CAN_PDC_ResetFuncOpt == Applied IGN Off → PDC_ResetPreWrngForOthers == Warning → PDC_ResetReqForOthers ==(Reset Request) 수신 | Q20: 1.리셋 정상 동작 WPC_ResetOpSta == ResetComplete 출력 1분 출력 | Y20: OK
A21: WPC-기능-007~009 | B21: WPC(SW)-기능-47-1 | C21: B+ = 13V 에서 CAN_PDC_ResetFuncOpt == Applied IGN Off → PDC_ResetPreWrngForOthers == Warning → PDC_ResetReqForOthers ==(Reset Request) 수신 | Q21: 1.리셋 정상 동작 WPC_ResetOpSta == ResetComplete 출력 1분 출력 | Y21: OK
A22: WPC-기능-007~009 | B22: WPC(SW)-기능-47-1 | C22: B+ = 14V 에서 CAN_PDC_ResetFuncOpt == Applied IGN Off → PDC_ResetPreWrngForOthers == Warning → PDC_ResetReqForOthers ==(Reset Request) 수신 | Q22: 1.리셋 정상 동작 WPC_ResetOpSta == ResetComplete 출력 1분 출력 | Y22: OK
A23: WPC-기능-007~009 | B23: WPC(SW)-기능-47-1 | C23: B+ = 15V 에서 CAN_PDC_ResetFuncOpt == Applied IGN Off → PDC_ResetPreWrngForOthers == Warning → PDC_ResetReqForOthers ==(Reset Request) 수신 | Q23: 1.리셋 정상 동작 WPC_ResetOpSta == ResetComplete 출력 1분 출력 | Y23: OK
A24: WPC-기능-007~009 | B24: WPC(SW)-기능-47-1 | C24: B+ = 16V 에서 CAN_PDC_ResetFuncOpt == Applied IGN Off → PDC_ResetPreWrngForOthers == Warning → PDC_ResetReqForOthers ==(Reset Request) 수신 | Q24: 1.리셋 정상 동작 WPC_ResetOpSta == ResetComplete 출력 1분 출력 | Y24: OK
A25: WPC-기능-007~009 | B25: WPC(SW)-기능-47-1 | C25: B+ = 17V 에서 CAN_PDC_ResetFuncOpt == Applied IGN Off → PDC_ResetPreWrngForOthers == Warning → PDC_ResetReqForOthers ==(Reset Request) 수신 | Q25: 1.리셋 정상 동작 WPC_ResetOpSta == ResetComplete 출력 1분 출력 | Y25: OK
A26: WPC-기능-007~009 | B26: WPC(SW)-기능-47-2 | C26: 위 case | Q26: SleepAck 진입후 Wake up 시 WPC_ResetOpSta == Normal 출력 | Y26: OK
A27: WPC-기능-007~009 | B27: WPC(SW)-기능-47-3 | C27: 위 위 case | Q27: PDC_ResetPreWrngForOthers == Warning 재 수신 시 WPC_ResetOpSta == Normal 출력 | Y27: OK
A28: WPC-기능-007~009 | B28: WPC(SW)-기능-47-4 | C28: CAN_PDC_ResetFuncOpt == Applied IGN Off → PDC_ResetPreWrngForOthers == Warning → PDC_ResetReqForOthers == RESERVED 수신 | Q28: 1. 리셋 실패 동작 시 WPC_ResetOpSta == ResetFail 1분간 출력 | Y28: OK
... A30: WPC-기능-007~009 | B30: WPC(SW)-기능-47-1 | C30: CAN_PDC_ResetFuncOpt == Applied IGN ON → PDC_ResetPreWrngForOthers == Warning → PDC_ResetReqForOthers ==(Reset Request) 수신 | Q30: 1.리셋 수행 하지 말 것 | Y30: OK
A31: WPC-기능-007~009 | B31: WPC(SW)-기능-46-1 | C31: CAN_PDC_ResetFuncOpt == Applied 상태에서 PDC 리셋 중 CCU_ForcedPowerOfReq == 0x1(On in the non-sleep state) 수신 시 | Q31: CCU_ForcedPowerOfReq 리셋 신호 무시 할것 (PDC 리셋 정상 동작 될 것) | Y31: OK | Z31: NFC 적용사양

Sheet WPC & NFC Mode Control
C2: WPC & NFC Mode Control Function
C4: WPC(SW)-기능-1,WPC(SW)-기능-2,WPC(SW)-기능-3,WPC(SW)-기능-4
C5: No | D5: 구분 | F5: 초기 조건 | J5: 평가조건1 | N5: 평가조건2 | R5: 평가조건3 | V5: 평가조건3 | Z5: 평가조건4 | AD5: 사양 결과 | AH5: 결과 | AI5: 비고 | AL5: 항목 수
AK6: 총 | AL6: =SUM(AL7:AL7) -> 232
C7: WPC(SW)-기능-2-1 | D7: b_WPCSW Option = On | F7: Off_Mode | J7: C_WPCNFCcmd == Searching On(HCE) | N7: - | R7: - | V7: - | Z7: - | AD7: NFC_Mode | AH7: N/A | AK7: OK | AL7: =COUNTIF(AH:AH,"OK") -> 232
C8: WPC(SW)-기능-2-2 | F8: 윗 case | J8: B+ 리셋 | N8: - | R8: - | V8: - | Z8: - | AD8: Off_Mode | AH8: N/A | AK8: NG | AL8: =COUNTIF(AH:AH,"NG") -> 0
C9: WPC(SW)-기능-2-3 | F9: Off_Mode | J9: C_WPCNFCcmd == Searching Off | N9: - | R9: - | V9: - | Z9: - | AD9: Off_Mode | AH9: N/A | AK9: N/A | AL9: =COUNTIF(AH:AH,"N/A") -> 56
C10: WPC(SW)-기능-4-1 | F10: Off_Mode | J10: C_WPCNFCcmd == Searching On(USIM) | N10: - | R10: - | V10: - | Z10: - | AD10: NFC_Mode | AH10: N/A | AI10: ty별 추가
C11: WPC(SW)-기능-2-4 | F11: 윗 case | J11: B+ 리셋 | N11: - | R11: - | V11: - | Z11: - | AD11: Off_Mode | AH11: N/A
C12: WPC(SW)-기능-2-5 | F12: Off_Mode | J12: C_WPCNFCcmd == Reserved | N12: - | R12: - | V12: - | Z12: - | AD12: Off_Mode | AH12: N/A
C13: WPC(SW)-기능-2-6 | F13: Off_Mode | J13: C_WPCNFCcmd == Invalid | N13: - | R13: - | V13: - | Z13: - | AD13: Off_Mode | AH13: N/A
C14: WPC(SW)-기능-4-2 | F14: Off_Mode | J14: C_IAUWPCNFCCmd == WPC NFC Polling(Search) | N14: - | R14: - | V14: - | Z14: - | AD14: NFC_Mode | AH14: N/A
C15: WPC(SW)-기능-2-7 | F15: 윗 case | J15: B+ 리셋 | N15: - | R15: - | V15: - | Z15: - | AD15: Off_Mode | AH15: N/A
C16: WPC(SW)-기능-2-8 | F16: Off_Mode | J16: C_IAUWPCNFCCmd == WPC NFC Deselect(Stop) | N16: - | R16: - | V16: - | Z16: - | AD16: Off_Mode | AH16: N/A
C17: WPC(SW)-기능-2-9 | F17: Off_Mode | J17: C_IAUWPCNFCCmd == Invalid | N17: - | R17: - | V17: - | Z17: - | AD17: Off_Mode | AH17: N/A
C18: WPC(SW)-기능-4-3 | F18: Off_Mode | J18: NFC Mode 진입 60초 이내 | N18: C_WPCNFCcmd == Searching On(HCE) | R18: - | V18: - | Z18: - | AD18: NFC Mode 재진입 60초 후 Off_Mode 진입 | AH18: N/A
C19: WPC(SW)-기능-2-10 | F19: Off_Mode | J19: NFC Mode 진입 60초 이내 | N19: C_WPCNFCcmd == Searching Off | R19: - | V19: - | Z19: - | AD19: Off_Mode | AH19: N/A
C20: WPC(SW)-기능-4-4 | F20: Off_Mode | J20: NFC Mode 진입 60초 이내 | N20: C_WPCNFCcmd == Searching On(USIM) | R20: - | V20: - | Z20: - | AD20: NFC Mode 재진입 60초 후 Off_Mode 진입 | AH20: N/A
C21: WPC(SW)-기능-4-5 | F21: Off_Mode | J21: NFC Mode 진입 60초 이내 | N21: C_IAUWPCNFCCmd == WPC NFC Polling(Search) | R21: - | V21: - | Z21: - | AD21: NFC Mode 재진입 60초 후 Off_Mode 진입 | AH21: N/A
C22: WPC(SW)-기능-2-11 | F22: Off_Mode | J22: NFC Mode 진입 60초 이내 | N22: C_IAUWPCNFCCmd == WPC NFC Deselect(Stop) | R22: - | V22: - | Z22: - | AD22: Off_Mode | AH22: N/A
... C29: WPC(SW)-기능-4-8 | F29: Off_Mode | J29: NFC Mode 진입 60초 이내 | N29: L_IGN1_IN = On | R29: C_IAUWPCNFCCmd == WPC NFC Polling(Search) | V29: - | Z29: - | AD29: NFC Mode 재진입 60초 후 WPC_Mode 진입 | AH29: N/A
C30: WPC(SW)-기능-2-13 | F30: Off_Mode | J30: NFC Mode 진입 60초 이내 | N30: L_IGN1_IN = On | R30: C_WPCNFCcmd == Searching Off | V30: - | AD30: WPC_Mode | AH30: N/A
C31: WPC(SW)-기능-2-14 | F31: Off_Mode | J31: NFC Mode 진입 60초 이내 | N31: L_IGN1_IN = On | R31: C_IAUWPCNFCCmd == WPC NFC Deselect(Stop) | V31: - | AD31: WPC_Mode | AH31: N/A
C32: WPC(SW)-기능-4-9 | F32: WPC_Mode | J32: C_WPCNFCcmd == Searching On(HCE) | N32: - | R32: - | V32: - | Z32: - | AD32: NFC_Mode | AH32: N/A
C33: WPC(SW)-기능-2-15 | F33: WPC_Mode | J33: B+ 리셋 | N33: - | R33: - | V33: - | Z33: - | AD33: WPC_Mode | AH33: N/A
C34: WPC(SW)-기능-2-16 | F34: WPC_Mode | J34: C_WPCNFCcmd == Searching Off | N34: - | R34: - | V34: - | Z34: - | AD34: WPC_Mode | AH34: N/A
C35: WPC(SW)-기능-4-10 | F35: WPC_Mode | J35: C_WPCNFCcmd == Searching On(USIM) | N35: - | R35: - | V35: - | Z35: - | AD35: NFC_Mode | AH35: N/A
C36: WPC(SW)-기능-2-17 | F36: WPC_Mode | J36: B+ 리셋 | N36: - | R36: - | V36: - | Z36: - | AD36: WPC_Mode | AH36: N/A
C37: WPC(SW)-기능-2-18 | F37: WPC_Mode | J37: C_WPCNFCcmd == Reserved | N37: - | R37: - | V37: - | Z37: - | AD37: WPC_Mode | AH37: N/A
C38: WPC(SW)-기능-2-19 | F38: WPC_Mode | J38: C_WPCNFCcmd == Invalid | N38: - | R38: - | V38: - | Z38: - | AD38: WPC_Mode | AH38: N/A
C39: WPC(SW)-기능-4-11 | F39: WPC_Mode | J39: C_IAUWPCNFCCmd == WPC NFC Polling(Search) | N39: - | R39: - | V39: - | Z39: - | AD39: NFC_Mode | AH39: N/A
C40: WPC(SW)-기능-2-20 | F40: WPC_Mode | J40: B+ 리셋 | N40: - | R40: - | V40: - | Z40: - | AD40: WPC_Mode | AH40: N/A
C41: WPC(SW)-기능-2-21 | F41: WPC_Mode | J41: C_IAUWPCNFCCmd == WPC NFC Deselect(Stop) | N41: - | R41: - | V41: - | Z41: - | AD41: WPC_Mode | AH41: N/A
C42: WPC(SW)-기능-2-22 | F42: WPC_Mode | J42: C_IAUWPCNFCCmd == Invalid | N42: - | R42: - | V42: - | Z42: - | AD42: WPC_Mode | AH42: N/A
C43: WPC(SW)-기능-1-1 | F43: WPC_Mode | J43: L_IGN1_IN = Off | N43: - | R43: - | V43: - | Z43: - | AD43: Off_Mode | AH43: N/A
C44: WPC(SW)-기능-1-2 | F44: WPC_Mode | J44: b_WPCSWOption = Off | N44: - | R44: - | V44: - | Z44: - | AD44: Off_Mode | AH44: N/A
C45: WPC(SW)-기능-4-12 | D45: b_WPCSW Option = Off | F45: Off_Mode | J45: b_WPCSWOption = Off | N45: L_IGN1_IN = Off | R45: C_WPCNFCcmd == Searching On(HCE) | V45: - | Z45: - | AD45: NFC_Mode | AH45: N/A
C46: WPC(SW)-기능-2-23 | F46: Off_Mode | J46: b_WPCSWOption = Off | N46: L_IGN1_IN = Off | R46: C_WPCNFCcmd == Searching Off | V46: - | Z46: - | AD46: Off_Mode | AH46: N/A
C47: WPC(SW)-기능-4-13 | F47: Off_Mode | J47: b_WPCSWOption = Off | N47: L_IGN1_IN = Off | R47: C_WPCNFCcmd == Searching On(USIM) | V47: - | Z47: - | AD47: NFC_Mode | AH47: N/A
B48: 전체CAN신호 대한 TC 필요 | C48: WPC(SW)-기능-4-14 | F48: Off_Mode | J48: b_WPCSWOption = Off | N48: L_IGN1_IN = Off | R48: C_IAUWPCNFCCmd == WPC NFC Polling(Search) | V48: - | Z48: - | AD48: NFC_Mode | AH48: N/A
...

Sheet Prevention of SMK LF
B2: WPC Prevention of SMK LF Interference Control Function
B4: WPC(SW)-기능-9,WPC(SW)-기능-10,WPC(SW)-기능-11
B5: No | C5: 구분 | E5: 초기 조건 | I5: 평가조건1 | M5: 평가조건2 | Q5: 평가조건3 | U5: 사양 결과 | Y5: 충전상태 | Z5: LED | AA5: 결과 | AB5: 비고
B7: WPC(SW)-기능-10-1 | C7: 휴대폰 거치 ICU 적용 | E7: L_IGN1_IN = On | I7: C_SMKOption == Off | M7: C_DrvDRSW === On | Q7: - | U7: LFSearching_Off | Y7: On | Z7: On | AA7: OK | AE7: RG3는 Non-SMK사양 없음
B8: WPC(SW)-기능-10-2 | E8: L_IGN1_IN = On | I8: C_SMKOption == Off | M8: C_DrvDRSW === On | Q8: C_AstDRSW === On | U8: LFSearching_Off | Y8: On | Z8: On | AA8: OK | AF8: 항목 수
B9: WPC(SW)-기능-10-3 | E9: L_IGN1_IN = On | I9: C_SMKOption == Off | M9: C_DrvDRSW === On | Q9: C_RLDRSW === On | U9: LFSearching_Off | Y9: On | Z9: On | AA9: OK | AE9: 총 | AF9: =SUM(AF10:AF12) -> 122
B10: WPC(SW)-기능-10-4 | E10: L_IGN1_IN = On | I10: C_SMKOption == Off | M10: C_DrvDRSW === On | Q10: C_RRDRSW === On | U10: LFSearching_Off | Y10: On | Z10: On | AA10: OK | AE10: OK | AF10: =COUNTIF(AA:AA,"OK") -> 122
B11: WPC(SW)-기능-10-5 | E11: L_IGN1_IN = On | I11: C_SMKOption == Off | M11: C_AstDRSW === On | Q11: - | U11: LFSearching_Off | Y11: On | Z11: On | AA11: OK | AE11: NG | AF11: =COUNTIF(AA:AA,"NG") -> 0
B12: WPC(SW)-기능-10-6 | E12: L_IGN1_IN = On | I12: C_SMKOption == Off | M12: C_AstDRSW === On | Q12: C_RLDRSW === On | U12: LFSearching_Off | Y12: On | Z12: On | AA12: OK | AE12: N/A | AF12: =COUNTIF(AA:AA,"N/A") -> 0
B13: WPC(SW)-기능-10-7 | E13: L_IGN1_IN = On | I13: C_SMKOption == Off | M13: C_AstDRSW === On | Q13: C_RRDRSW === On | U13: LFSearching_Off | Y13: On | Z13: On | AA13: OK
B14: WPC(SW)-기능-10-8 | E14: L_IGN1_IN = On | I14: C_SMKOption == Off | M14: C_RLDRSW === On | Q14: - | U14: LFSearching_Off | Y14: On | Z14: On | AA14: OK
B15: WPC(SW)-기능-10-9 | E15: L_IGN1_IN = On | I15: C_SMKOption == Off | M15: C_RLDRSW === On | Q15: C_RRDRSW === On | U15: LFSearching_Off | Y15: On | Z15: On | AA15: OK
B16: WPC(SW)-기능-10-10 | E16: L_IGN1_IN = On | I16: C_SMKOption == Off | M16: C_RRDRSW === On | Q16: - | U16: LFSearching_Off | Y16: On | Z16: On | AA16: OK
B17: WPC(SW)-기능-9-1 | E17: L_IGN1_IN = On | I17: C_SMKOption == Off | M17: C_LFSearchingOn == On | Q17: - | U17: LFSearching_Off | Y17: On | Z17: On | AA17: OK
B18: WPC(SW)-기능-9-2 | E18: L_IGN1_IN = On | I18: C_SMKOption == Off | M18: C_DrvDRSW === On | Q18: C_LFSearchingOn == On | U18: LFSearching_Off | Y18: On | Z18: On | AA18: OK
B19: WPC(SW)-기능-9-3 | E19: L_IGN1_IN = On | I19: C_SMKOption == Off | M19: C_AstDRSW === On | Q19: C_LFSearchingOn == On | U19: LFSearching_Off | Y19: On | Z19: On | AA19: OK
B20: WPC(SW)-기능-9-4 | E20: L_IGN1_IN = On | I20: C_SMKOption == Off | M20: C_RLDRSW === On | Q20: C_LFSearchingOn == On | U20: LFSearching_Off | Y20: On | Z20: On | AA20: OK
B21: WPC(SW)-기능-9-5 | E21: L_IGN1_IN = On | I21: C_SMKOption == Off | M21: C_RRDRSW === On | Q21: C_LFSearchingOn == On | U21: LFSearching_Off | Y21: On | Z21: On | AA21: OK
B22: WPC(SW)-기능-10-11 | E22: C_SMKOption == On | I22: C_DrvDRSW === On | M22: L_IGN1_IN = On | Q22: - | U22: LFSearching_On | Y22: Off | Z22: Off | AA22: OK
B23: WPC(SW)-기능-10-12 | E23: L_IGN1_IN = On | I23: C_SMKOption == On | M23: C_DrvDRSW === On | Q23: - | U23: LFSearching_On | Y23: Off | Z23: Off | AA23: OK
B24: WPC(SW)-기능-10-13 | E24: 윗 case | I24: B+ 리셋 | M24: - | Q24: - | U24: LFSearching_On | Y24: Off | Z24: Off | AA24: OK
... B57: WPC(SW)-기능-10-24 | E57: L_IGN1_IN = On | I57: C_SMKOption == On | M57: C_LFSearchingOn == On | Q57: C_SMKOption == Off | U57: 즉시 LFSearching_On = Off | Y57: Off -> On | Z57: Off -> On | AA57: OK
B58: WPC(SW)-기능-10-25 | E58: L_IGN1_IN = On | I58: C_SMKOption == On | M58: C_DrvDRSW === On | Q58: WPCStatus = NFC_Mode | U58: 즉시 LFSearching_On = Off | Y58: Off | Z58: Off | AA58: OK | AB58: NFC 사양
B59: WPC(SW)-기능-10-26 | E59: L_IGN1_IN = On | I59: C_SMKOption == On | M59: C_AstDRSW === On | Q59: WPCStatus = NFC_Mode | U59: 즉시 LFSearching_On = Off | Y59: Off | Z59: Off | AA59: OK | AB59: NFC 사양
B60: WPC(SW)-기능-10-27 | E60: L_IGN1_IN = On | I60: C_SMKOption == On | M60: C_RLDRSW === On | Q60: WPCStatus = NFC_Mode | U60: 즉시 LFSearching_On = Off | Y60: Off | Z60: Off | AA60: OK | AB60: NFC 사양
B61: WPC(SW)-기능-10-28 | E61: L_IGN1_IN = On | I61: C_SMKOption == On | M61: C_RRDRSW === On | Q61: WPCStatus = NFC_Mode | U61: 즉시 LFSearching_On = Off | Y61: Off | Z61: Off | AA61: OK | AB61: NFC 사양
B62: WPC(SW)-기능-10-29 | E62: L_IGN1_IN = On | I62: C_SMKOption == On | M62: C_LFSearchingOn == On | Q62: WPCStatus = NFC_Mode | U62: 즉시 LFSearching_On = Off | Y62: Off | Z62: Off | AA62: OK | AB62: NFC 사양
B63: WPC(SW)-기능-10-30 | E63: L_IGN1_IN = On | I63: C_SMKOption == On | M63: C_DrvDRSW === On | Q63: WPCStatus = Off_Mode | U63: 즉시 LFSearching_On = Off | Y63: Off | Z63: Off | AA63: OK
B64: WPC(SW)-기능-10-31 | E64: L_IGN1_IN = On | I64: C_SMKOption == On | M64: C_AstDRSW === On | Q64: WPCStatus = Off_Mode | U64: 즉시 LFSearching_On = Off | Y64: Off | Z64: Off | AA64: OK
B65: WPC(SW)-기능-10-32 | E65: L_IGN1_IN = On | I65: C_SMKOption == On | M65: C_RLDRSW === On | Q65: WPCStatus = Off_Mode | U65: 즉시 LFSearching_On = Off | Y65: Off | Z65: Off | AA65: OK
B66: WPC(SW)-기능-10-33 | E66: L_IGN1_IN = On | I66: C_SMKOption == On | M66: C_RRDRSW === On | Q66: WPCStatus = Off_Mode | U66: 즉시 LFSearching_On = Off | Y66: Off | Z66: Off | AA66: OK
B67: WPC(SW)-기능-10-34 | E67: L_IGN1_IN = On | I67: C_SMKOption == On | M67: C_LFSearchingOn == On | Q67: WPCStatus = Off_Mode | U67: 즉시 LFSearching_On = Off | Y67: Off | Z67: Off | AA67: OK
B68: WPC(SW)-기능-10-35 | C68: 휴대폰 거치 SBCM 적용 | E68: L_IGN1_IN = On | I68: C_SMKOption == Off && Lathch_TypeOption_DRV = ON | M68: C_DrvDRSW_SBCM == On | Q68: - | U68: LFSearching_Off | Y68: On | Z68: On | AA68: OK
B69: WPC(SW)-기능-10-36 | E69: L_IGN1_IN = On | I69: C_SMKOption == Off && Lathch_TypeOption_DRV = ON | M69: C_DrvDRSW_SBCM == On | Q69: C_AstDRSW_SBCM === On | U69: LFSearching_Off | Y69: On | Z69: On | AA69: OK
B70: WPC(SW)-기능-10-37 | E70: L_IGN1_IN = On | I70: C_SMKOption == Off && Lathch_TypeOption_DRV = ON | M70: C_DrvDRSW_SBCM == On | Q70: C_RLDRSW_SBCM == On | U70: LFSearching_Off | Y70: On | Z70: On | AA70: OK
B71: WPC(SW)-기능-10-38 | E71: L_IGN1_IN = On | I71: C_SMKOption == Off && Lathch_TypeOption_DRV = ON | M71: C_DrvDRSW_SBCM == On | Q71: C_RRDRSW_SBCM== On | U71: LFSearching_Off | Y71: On | Z71: On | AA71: OK
B72: WPC(SW)-기능-10-39 | E72: L_IGN1_IN = On | I72: C_SMKOption == Off && Lathch_TypeOption_DRV = ON | M72: C_AstDRSW_SBCM === On | Q72: - | U72: LFSearching_Off | Y72: On | Z72: On | AA72: OK
B73: WPC(SW)-기능-10-40 | E73: L_IGN1_IN = On | I73: C_SMKOption == Off && Lathch_TypeOption_DRV = ON | M73: C_AstDRSW_SBCM === On | Q73: C_RLDRSW_SBCM == On | U73: LFSearching_Off | Y73: On | Z73: On | AA73: OK
B74: WPC(SW)-기능-10-41 | E74: L_IGN1_IN = On | I74: C_SMKOption == Off && Lathch_TypeOption_DRV = ON | M74: C_AstDRSW_SBCM === On | Q74: C_RRDRSW_SBCM== On | U74: LFSearching_Off | Y74: On | Z74: On | AA74: OK
B75: WPC(SW)-기능-10-42 | E75: L_IGN1_IN = On | I75: C_SMKOption == Off && Lathch_TypeOption_DRV = ON | M75: C_RLDRSW_SBCM == On | Q75: - | U75: LFSearching_Off | Y75: On | Z75: On | AA75: OK
...

Sheet Over Current Detecting
B2: WPC Over Current Detecting Control Function
B4: WPC(SW)기능-12
B5: No | C5: 구분 | E5: x | I5: 평가조건1 | M5: 평가조건2 | Q5: 사양 결과 | U5: 충전상태 | V5: LED | W5: 결과 | X5: 비고
AB6: 항목 수
B7: WPC(SW)기능-12-1 | C7: IGN ON | E7: b_WPCStatus = WPCMode | I7: 전류 4.5A 미만 | M7: - | Q7: b_CurrentFault = Off | U7: On | V7: On | W7: OK | AA7: 총 | AB7: =SUM(AB8:AB9) -> 7
B8: WPC(SW)기능-12-2 | E8: b_WPCStatus = WPCMode | I8: 전류 4.5A 이상 | M8: 150ms 미만 | Q8: b_CurrentFault = Off | U8: On | V8: On | W8: OK | AA8: OK | AB8: =COUNTIF(W:W,"OK") -> 7
B9: WPC(SW)기능-12-3 | E9: b_WPCStatus = WPCMode | I9: 전류 4.5A 이상 | M9: 150ms 이상 | Q9: b_CurrentFault = On | U9: Off | V9: Off | W9: OK | AA9: NG | AB9: =COUNTIF(W:W,"NG") -> 0
B11: WPC(SW)기능-13
B12: No | C12: 구분 | E12: x | I12: 평가조건1 | M12: 평가조건2 | Q12: 사양 결과 | U12: 충전상태 | V12: LED | W12: 결과 | X12: 비고
B14: WPC(SW)기능-13-1 | C14: IGN ON | E14: WPC(SW)기능-12-3 case | I14: 5초마다 과전류 모니터링 | M14: 과전류 10회 미만 | Q14: b_CurrentFault = Off | U14: On | V14: On | W14: OK
B15: WPC(SW)기능-13-2 | E15: WPC(SW)기능-12-3 case | I15: 5초마다 과전류 모니터링 | M15: 과전류 10회 이상 | Q15: b_CurrentFault = On | U15: Off | V15: Off | W15: OK
B17: WPC(SW)기능-14
B18: No | C18: 구분 | E18: x | I18: 평가조건1 | M18: 평가조건2 | Q18: 사양 결과 | U18: 충전상태 | V18: LED | W18: 결과 | X18: 비고
B20: WPC(SW)기능-14-1 | C20: IGN ON | E20: WPC(SW)기능-13-2 | I20: B+리셋 | M20: - | Q20: b_CurrentFault = Off | U20: On | V20: On | W20: OK
B21: WPC(SW)기능-14-2 | E21: WPC(SW)기능-13-2 | I21: b_WPCStatus != WPCMode | M21: - | Q21: b_CurrentFault = Off | U21: On | V21: On | W21: OK
AA24: N/A

Sheet Over Voltage & Under Voltage
B2: Over Voltage & Under Voltage
B4: WPC(SW)-동작성능-6
B5: No | C5: 구분 | E5: 초기 조건 | I5: 평가조건1 | M5: 평가조건2 | Q5: 사양 결과 | U5: 충전상태 | V5: LED | W5: 결과 | X5: 비고
B7: WPC(SW)-동작성능-6-1 | C7: 고속 무선충전 | E7: 9.0V 미만 | I7: - | M7: - | Q7: 충전 미진입 | U7: Off | V7: Off | W7: OK | AB7: 항목 수
B8: WPC(SW)-동작성능-6-2 | E8: 9.0V 미만 | I8: 9.0V 이상 | M8: - | Q8: 충전 진입 | U8: On | V8: On | W8: OK | AA8: 총 | AB8: =SUM(AB9:AB11) -> 46
B9: WPC(SW)-동작성능-6-3 | E9: 9.0V 미만 | I9: 9.0V 이상 | M9: 16.5V 이상 | Q9: 충전 중단 | U9: On -> Off | V9: On -> Off | W9: OK | AA9: OK | AB9: =COUNTIF(U7:W44,"OK") -> 46
B10: WPC(SW)-동작성능-6-4 | E10: 16.0V 초과 | I10: - | M10: - | Q10: 충전 미진입 | U10: Off | V10: Off | W10: OK | AA10: NG | AB10: =COUNTIF(U7:W44,"NG") -> 0
B11: WPC(SW)-동작성능-6-5 | E11: 16.0V 초과 | I11: 16.0V 이하 | M11: - | Q11: 충전 진입 | U11: On | V11: On | W11: OK | AA11: N/A | AB11: =COUNTIF(U7:W44,"N/A") -> 0
B12: WPC(SW)-동작성능-6-6 | E12: 16.0V 초과 | I12: 16.0V 이하 | M12: 8.5V 이하 | Q12: 충전 중단 | U12: On -> Off | V12: On -> Off | W12: OK
B14: No | C14: 구분 | E14: 초기 조건 | I14: 평가조건1 | M14: 평가조건2 | Q14: 사양 결과 | U14: 충전상태 | V14: LED | W14: 결과
B16: WPC(SW)-동작성능-6-7 | C16: 일반 무선충전 | E16: 9.0V 미만 | I16: - | M16: - | Q16: 충전 미진입 | U16: Off | V16: Off | W16: OK
B17: WPC(SW)-동작성능-6-8 | E17: 9.0V 미만 | I17: 9.0V 이상 | M17: - | Q17: 충전 진입 | U17: On | V17: On | W17: OK
B18: WPC(SW)-동작성능-6-9 | E18: 9.0V 미만 | I18: 9.0V 이상 | M18: 16.5V 이상 | Q18: 충전 중단 | U18: On -> Off | V18: On -> Off | W18: OK
B19: WPC(SW)-동작성능-6-10 | E19: 16.0V 초과 | I19: - | M19: - | Q19: 충전 미진입 | U19: Off | V19: Off | W19: OK
B20: WPC(SW)-동작성능-6-11 | E20: 16.0V 초과 | I20: 16.0V 이하 | M20: - | Q20: 충전 진입 | U20: On | V20: On | W20: OK
B21: WPC(SW)-동작성능-6-12 | E21: 16.0V 초과 | I21: 16.0V 이하 | M21: 8.5V 이하 | Q21: 충전 중단 | U21: On -> Off | V21: On -> Off | W21: OK
B23: No | C23: 구분 | E23: 초기 조건 | I23: 사양 결과 | M23: 충전상태 | Q23: LED | U23: EPP 휴대폰 | X23: 비고
U24: 휴대폰 1 | V24: 휴대폰 2 | W24: 휴대폰 3
B25: 1 | C25: 2T (높이) | E25: 12V | I25: 충전 진입 | M25: On | Q25: On | U25: OK | V25: OK | W25: OK | X25: 케이스 미 장착 시 4T | AA25: 16V 까지 FOD 진입 없이 정상 충전되야함
B26: 2 | E26: 13V | I26: 충전 진입 | M26: On | Q26: On | U26: OK | V26: OK | W26: OK
B27: 3 | E27: 14V | I27: 충전 진입 | M27: On | Q27: On | U27: OK | V27: OK | W27: OK
B28: 4 | E28: 15V | I28: 충전 진입 | M28: On | Q28: On | U28: OK | V28: OK | W28: OK
B29: 5 | E29: 16V | I29: 충전 진입 | M29: On | Q29: On | U29: OK | V29: OK | W29: OK
B30: 1 | C30: 4T (높이) | E30: 12V | I30: 충전 진입 | M30: On | Q30: On | U30: OK | V30: OK | W30: OK | X30: 케이스 미 장착 시 6T
B31: 2 | E31: 13V | I31: 충전 진입 | M31: On | Q31: On | U31: OK | V31: OK | W31: OK
B32: 3 | E32: 14V | I32: 충전 진입 | M32: On | Q32: On | U32: OK | V32: OK | W32: OK
B33: 4 | E33: 15V | I33: 충전 진입 | M33: On | Q33: On | U33: OK | V33: OK | W33: OK
B34: 5 | E34: 16V | I34: 충전 진입 | M34: On | Q34: On | U34: OK | V34: OK | W34: OK
B36: No | C36: 구분 | E36: 초기 조건 | I36: 평가조건1 | M36: 평가조건2 | Q36: 사양 결과 | U36: 충전상태 | V36: LED | W36: 결과
B38: WPC(SW)-동작성능-6-13 | C38: 휴대폰 충전 W | E38: 12V | I38: 휴대폰 거치(갤럭시) | M38: 충전 120s 후 | Q38: 15W 이상 충전 될 것 | U38: On | V38: On | W38: OK
B39: WPC(SW)-동작성능-6-14 | E39: 12V | I39: 휴대폰 거치(아이폰) | M39: 충전 120s 후 | Q39: 7.5W 이상 충전 될 것 | U39: On | V39: On | W39: OK
B41: No | C41: 구분 | E41: 초기 조건 | I41: 평가조건1 | M41: 평가조건2 | Q41: 사양 결과 | U41: 충전상태 | V41: LED | W41: 결과
B43: WPC(SW)-동작성능-6-15 | C43: 비정상 거치 | E43: 12V | I43: 휴대폰 비 정상 거치(갤럭시) | M43: 휴대폰 정상 거치(갤럭시) | Q43: 즉시 충전 될 것 | U43: On | V43: On | W43: OK
B44: WPC(SW)-동작성능-6-16 | E44: 12V | I44: 휴대폰 비 정상 거치(아이폰) | M44: 휴대폰 정상 거치(아이폰) | Q44: 즉시 충전 될 것 | U44: On | V44: On | W44: OK
B46: WPC(SW)-기능-7
A47: ` | B47: No | C47: 구분 | E47: 초기 조건 | I47: 평가조건1 | M47: 평가조건2 | Q47: 사양 결과 | U47: 충전상태 | V47: LED | W47: 결과
B49: WPC(SW)-기능-7-1 | C49: 충전 상태 | E49: 12V | I49: 휴대폰 정상 거치(갤럭시 미완충) | Q49: 즉시 충전 될 것 | U49: On | V49: Amber | W49: OK
B50: WPC(SW)-기능-7-2 | E50: 12V | I50: 휴대폰 정상 거치(갤럭시 완 충) | Q50: 즉시 충전 될 것 | U50: On | V50: Green | W50: OK
B51: WPC(SW)-기능-7-3 | E51: 12V | I51: 휴대폰 정상 거치(아이폰 완 충) | Q51: 즉시 충전 될 것 | U51: On | V51: Amber | W51: OK
B53: NO | C53: MESSAGE | I53: 저전압 | Q53: 고전압 | Y53: 결과 | Z53: 비고
...

Sheet WPC Leaving Phone
B2: WPC Leaving Phone Control Function
B4: WPC(SW)-기능-6,WPC(SW)-기능-8
B5: No | C5: 구분 | E5: 초기 조건 | I5: 평가조건1 | M5: 평가조건2 | Q5: 평가조건3 | U5: 평가조건4 | Y5: 사양 결과 | AC5: 결과 | AD5: 비고
AL6: 항목 수
B7: WPC(SW)-기능-6-1 | C7: b_WPCSW Option == On | E7: L_IGN1_IN = On | I7: 휴대폰 거치 | M7: L_IGN1_IN = Off | Q7: - | U7: - | Y7: 1000ms 이내 C_WPCWarning 0x01 송신 | AC7: N/A | AD7: 측정값 : 750ms | AG7: RG3는 Non-SMK사양 없음 | AK7: 총 | AL7: =SUM(AL8:AL10) -> 156
B8: WPC(SW)-기능-6-2 | E8: 휴대폰 미거치 | I8: L_IGN1_IN = On | M8: L_IGN1_IN = Off | Q8: - | U8: - | Y8: 동작없음 | AC8: N/A | AK8: OK | AL8: =COUNTIF(AC$2:AC$1048576,"OK") -> 32
B9: WPC(SW)-기능-6-3 | E9: L_IGN1_IN = On | I9: 미완충 휴대폰 거치 (Signal Strength 송신) | M9: L_IGN1_IN = Off | Q9: - | U9: - | Y9: Cellphone On The Pad 1분 송신 후 Cellphone Reminder 500ms 송신 | AC9: N/A | AD9: 삼성, LG 휴대폰 | AK9: NG | AL9: =COUNTIF(AC$2:AC$1048576,"NG") -> 0
B10: WPC(SW)-기능-6-4 | E10: 윗 case | I10: 방치알림 60s 송신 후 | M10: - | Q10: - | U10: - | Y10: NM Message Sleep IND | AC10: N/A | AG10: 원 코일 - LPCD 천이 후 Sleep 진입 | AK10: N/A | AL10: =COUNTIF(AC$2:AC$1048576,"N/A") -> 124
B11: WPC(SW)-기능-6-5 | E11: 윗 case | I11: Any Door Open | M11: - | Q11: - | U11: - | Y11: 동작없음 | AC11: N/A | AG11: 원 코일 - 운전석 도어 오픈 시 LPCD Mode 동작 됨
B12: WPC(SW)-기능-6-6 | E12: L_IGN1_IN = On | I12: 완충 휴대폰 거치 (Signal Strength 송신) | M12: L_IGN1_IN = Off | Q12: - | U12: - | Y12: Cellphone On The Pad 1분 송신 후 Cellphone Reminder 500ms 송신 | AC12: N/A | AD12: 삼성, LG 휴대폰
B13: WPC(SW)-기능-6-7 | E13: 윗 case | I13: 방치알림 60s 송신 후 | M13: - | Q13: - | U13: - | Y13: NM Message Sleep IND | AC13: N/A | AG13: 원 코일 - LPCD 천이 후 Sleep 진입
B14: WPC(SW)-기능-6-8 | E14: 윗 case | I14: Any Door Open | M14: - | Q14: - | U14: - | Y14: 동작없음 | AC14: N/A | AG14: 원 코일 - 운전석 도어 오픈 시 LPCD Mode 동작 됨
B15: WPC(SW)-기능-6-9 | E15: L_IGN1_IN = On | I15: 완충 휴대폰 거치 | M15: L_IGN1_IN = Off | Q15: - | U15: - | Y15: Cellphone On The Pad 1분 송신 후 Cellphone Reminder 500ms 송신 | AC15: N/A | AD15: 아이폰
B16: WPC(SW)-기능-6-10 | E16: 윗 case | I16: 방치알림 60s 송신 후 | M16: - | Q16: - | U16: - | Y16: NM Message Sleep IND | AC16: N/A | AG16: 원 코일 - LPCD 천이 후 Sleep 진입
B17: WPC(SW)-기능-6-11 | E17: 윗 case | I17: Any Door Open | M17: - | Q17: - | U17: - | Y17: 동작없음 | AC17: N/A | AG17: 원 코일 - 운전석 도어 오픈 시 LPCD Mode 동작 됨
B18: WPC(SW)-기능-6-12 | E18: L_IGN1_IN = Off | I18: 휴대폰 거치 | M18: L_IGN1_IN = On | Q18: L_IGN1_IN = Off | U18: - | Y18: Cellphone On The Pad 1분 송신 후 Cellphone Reminder 500ms 송신 | AC18: N/A
B19: WPC(SW)-기능-6-13 | E19: 윗 case | I19: 방치알림 60s 송신 후 | M19: - | Q19: - | U19: - | Y19: NM Message Sleep IND | AC19: N/A | AG19: 원 코일 - LPCD 천이 후 Sleep 진입
B20: WPC(SW)-기능-6-14 | E20: 윗 case | I20: Any Door Open | M20: - | Q20: - | U20: - | Y20: 동작없음 | AC20: N/A | AG20: 원 코일 - 운전석 도어 오픈 시 LPCD Mode 동작 됨
B21: WPC(SW)-기능-6-15 | E21: L_IGN1_IN = On | I21: L_IGN1_IN = Off 동시에 휴대폰 거치 | M21: - | Q21: - | U21: - | Y21: Cellphone On The Pad 1분 송신 후 Cellphone Reminder 500ms 송신 | AC21: N/A
B22: WPC(SW)-기능-6-16 | E22: L_IGN1_IN = On | I22: 휴대폰 거치 & C_SMKOption == On && (Latch_TypeOption_DRV= ON SBCM 사양시) | M22: L_IGN1_IN = Off 동시에 Drv 도어 오픈 | Q22: - | U22: - | Y22: Cellphone On The Pad 1분 송신 | AC22: N/A
B23: WPC(SW)-기능-6-17 | E23: L_IGN1_IN = On | I23: 휴대폰 거치 & C_SMKOption == On && (Latch_TypeOption_DRV= ON SBCM 사양시) | M23: L_IGN1_IN = Off 동시에 Drv 도어 오픈 | Q23: - | U23: - | Y23: Cellphone On The Pad 6s 송신 | AC23: N/A
B24: WPC(SW)-기능-6-18 | E24: L_IGN1_IN = On | I24: 휴대폰 거치 & C_SMKOption == On && (Latch_TypeOption_DRV= ON SBCM 사양시) | M24: L_IGN1_IN = Off 동시에 Ast 도어 오픈 | Q24: - | U24: - | Y24: Cellphone On The Pad 1분 송신 | AC24: N/A
B25: WPC(SW)-기능-6-19 | E25: L_IGN1_IN = On | I25: 휴대폰 거치 & C_SMKOption == On && (Latch_TypeOption_DRV= ON SBCM 사양시) | M25: L_IGN1_IN = Off 동시에 FR 도어 오픈 | Q25: - | U25: - | Y25: Cellphone On The Pad 1분 송신 | AC25: N/A
B26: WPC(SW)-기능-6-20 | E26: L_IGN1_IN = On | I26: 휴대폰 거치 & C_SMKOption == On && (Latch_TypeOption_DRV= ON SBCM 사양시) | M26: L_IGN1_IN = Off 동시에 RR 도어 오픈 | Q26: - | U26: - | Y26: Cellphone On The Pad 1분 송신 | AC26: N/A
B27: WPC(SW)-기능-6-21 | E27: L_IGN1_IN = On | I27: 휴대폰 거치 & C_SMKOption == On && (Latch_TypeOption_DRV= ON SBCM 사양시) | M27: L_IGN1_IN = Off | Q27: C_DrvDRSW == ON or C_DrvDRSW_SBCM == ON | U27: - | Y27: Cellphone On The Pad 1분 송신 | AC27: N/A | AG27: 원코일 - 드라이보 ON/CLOSE 시 LPCD Mode 동작하여 Cellphone On The Pad 1분 송신 미적용
B28: WPC(SW)-기능-6-22 | E28: L_IGN1_IN = On | I28: 휴대폰 거치 & C_SMKOption == On && (Latch_TypeOption_DRV= ON SBCM 사양시) | M28: L_IGN1_IN = Off | Q28: C_DrvDRSW == ON or C_DrvDRSW_SBCM == ON | U28: - | Y28: Cellphone On The Pad 출력 | AC28: N/A
B29: WPC(SW)-기능-6-23 | E29: L_IGN1_IN = On | I29: 휴대폰 거치 & C_SMKOption == On && (Latch_TypeOption_DRV= ON SBCM 사양시) | M29: L_IGN1_IN = Off 동시에 Ast 도어 오픈 | Q29: - | U29: - | Y29: Cellphone On The Pad 6s 송신 | AC29: N/A
B30: WPC(SW)-기능-6-24 | E30: L_IGN1_IN = On | I30: 휴대폰 거치 & C_SMKOption == On && (Latch_TypeOption_DRV= ON SBCM 사양시) | M30: C_DrvDRSW == ON or C_DrvDRSW_SBCM == ON | Q30: L_IGN1_IN = Off | U30: - | Y30: Cellphone On The Pad 1분 송신 | AC30: N/A
B31: WPC(SW)-기능-6-25 | E31: L_IGN1_IN = On | I31: 휴대폰 거치 & C_SMKOption == On && (Latch_TypeOption_DRV= ON SBCM 사양시) | M31: C_DrvDRSW == ON or C_DrvDRSW_SBCM == ON | Q31: L_IGN1_IN = Off | U31: - | Y31: Cellphone On The Pad 6s 송신 | AC31: N/A
B32: WPC(SW)-기능-6-26 | E32: L_IGN1_IN = Off | I32: 휴대폰 거치 & C_SMKOption == On && (Latch_TypeOption_DRV= ON SBCM 사양시) | M32: C_DrvDRSW == ON or C_DrvDRSW_SBCM == ON | Q32: L_IGN1_IN = On | U32: L_IGN1_IN = Off | Y32: Cellphone On The Pad 1분 송신 | AC32: N/A
B33: WPC(SW)-기능-6-27 | E33: L_IGN1_IN = Off | I33: 휴대폰 거치 & C_SMKOption == On && (Latch_TypeOption_DRV= ON SBCM 사양시) | M33: C_DrvDRSW == ON or C_DrvDRSW_SBCM == ON | Q33: L_IGN1_IN = On | U33: L_IGN1_IN = Off | Y33: Cellphone On The Pad 출력 | AC33: N/A | AD33: LPCD 사양
B34: WPC(SW)-기능-6-28 | E34: L_IGN1_IN = On | I34: 휴대폰 거치 & C_SMKOption == On && (Latch_TypeOption_DRV= ON SBCM 사양시) | M34: L_IGN1_IN = Off | Q34: C_AstDRSW == ON or C_AstDRSW_SBCM == ON | U34: - | Y34: Cellphone On The Pad 1분 송신 | AC34: N/A
B35: WPC(SW)-기능-6-29 | E35: L_IGN1_IN = Off | I35: 휴대폰 거치 & C_SMKOption == On && (Latch_TypeOption_DRV= ON SBCM 사양시) | M35: C_DrvDRSW == ON or C_DrvDRSW_SBCM == ON | Q35: L_IGN1_IN = On | U35: L_IGN1_IN = Off | Y35: Cellphone On The Pad 6s 송신 | AC35: N/A
B36: WPC(SW)-기능-6-30 | E36: L_IGN1_IN = On | I36: 휴대폰 거치 & C_SMKOption == On && (Latch_TypeOption_DRV= ON SBCM 사양시) | M36: C_AstDRSW == ON or C_AstDRSW_SBCM == ON | Q36: L_IGN1_IN = Off | U36: - | Y36: Cellphone On The Pad 1분 송신 | AC36: N/A
B37: WPC(SW)-기능-6-31 | E37: L_IGN1_IN = On | I37: 휴대폰 거치 & C_SMKOption == On && (Latch_TypeOption_DRV= ON SBCM 사양시) | M37: C_AstDRSW == ON or C_AstDRSW_SBCM == ON | Q37: L_IGN1_IN = Off | U37: - | Y37: Cellphone On The Pad 6s 송신 | AC37: N/A
B38: WPC(SW)-기능-6-32 | E38: L_IGN1_IN = Off | I38: 휴대폰 거치 & C_SMKOption == On && (Latch_TypeOption_DRV= ON SBCM 사양시) | M38: C_AstDRSW == ON or C_AstDRSW_SBCM == ON | Q38: L_IGN1_IN = On | U38: L_IGN1_IN = Off | Y38: Cellphone On The Pad 1분 송신 | AC38: N/A
B39: WPC(SW)-기능-6-33 | E39: L_IGN1_IN = On | I39: 휴대폰 거치 & C_SMKOption == On && (Latch_TypeOption_DRV= ON SBCM 사양시) | M39: L_IGN1_IN = Off | Q39: C_RLDRSW == ON or C_RLDRSW_SBCM == ON | U39: - | Y39: Cellphone On The Pad 1분 송신 후 Cellphone Reminder 500ms 송신 | AC39: N/A
B40: WPC(SW)-기능-6-34 | E40: L_IGN1_IN = On | I40: 휴대폰 거치 & C_SMKOption == On && (Latch_TypeOption_DRV= ON SBCM 사양시) | M40: C_RLDRSW == ON or C_RLDRSW_SBCM == ON | Q40: L_IGN1_IN = Off | U40: - | Y40: Cellphone On The Pad 1분 송신 후 Cellphone Reminder 500ms 송신 | AC40: N/A
B41: WPC(SW)-기능-6-35 | E41: L_IGN1_IN = Off | I41: 휴대폰 거치 & C_SMKOption == On && (Latch_TypeOption_DRV= ON SBCM 사양시) | M41: C_RLDRSW == ON or C_RLDRSW_SBCM == ON | Q41: L_IGN1_IN = On | U41: L_IGN1_IN = Off | Y41: Cellphone On The Pad 1분 송신 후 Cellphone Reminder 500ms 송신 | AC41: N/A
B42: WPC(SW)-기능-6-36 | E42: L_IGN1_IN = On | I42: 휴대폰 거치 & C_SMKOption == On && (Latch_TypeOption_DRV= ON SBCM 사양시) | M42: L_IGN1_IN = Off | Q42: C_RRDRSW == ON or C_RRDRSW_SBCM == ON | U42: - | Y42: Cellphone On The Pad 1분 송신 후 Cellphone Reminder 500ms 송신 | AC42: N/A
...

Sheet Temperature Sensor Error
B2: WPC Temperature Sensor Error Detecting Control Function
B4: WPC(SW)-기능-15, WPC(SW)-기능-16
B5: No | C5: 구분 | E5: 초기 조건 | I5: 평가조건1 | M5: 평가조건2 | Q5: 사양 결과 | U5: 충전상태 | V5: LED | W5: 결과 | X5: 비고
B7: WPC(SW)-기능-15-1 | C7: 휴대폰 거치 | E7: WPCStatus = WPC_Mode | I7: 온도센서 모두 정상 | M7: 1번 온도센서 에러 2s 미만 유지 | Q7: 온도센서 에러 Off | U7: On | V7: On | W7: OK | X7: 온도센서 쇼트 or 오픈 | AB7: 항목 수
B8: WPC(SW)-기능-15-2 | E8: WPCStatus = WPC_Mode | I8: 온도센서 모두 정상 | M8: 2번 온도센서 에러 2s 미만 유지 | Q8: 온도센서 에러 Off | U8: On | V8: On | W8: N/A | AA8: 총 | AB8: =SUM(AB9:AB11) -> 30
B9: WPC(SW)-기능-15-3 | E9: WPCStatus = WPC_Mode | I9: 온도센서 모두 정상 | M9: 3번 온도센서 에러 2s 미만 유지 | Q9: 온도센서 에러 Off | U9: On | V9: On | W9: N/A | AA9: OK | AB9: =COUNTIF(W:W,"OK") -> 8
B10: WPC(SW)-기능-15-4 | E10: WPCStatus = WPC_Mode | I10: 온도센서 모두 정상 | M10: 1번 온도센서 에러 2s 이상 유지 | Q10: 온도센서 에러 On | U10: Off | V10: Off | W10: OK | AA10: NG | AB10: =COUNTIF(W:W,"NG") -> 0
B11: WPC(SW)-기능-15-5 | E11: 윗 case | I11: B+ 리셋 | M11: - | Q11: 온도센서 에러 On | U11: Off | V11: Off | W11: OK | AA11: N/A | AB11: =COUNTIF(W:W,"N/A") -> 22
B12: WPC(SW)-기능-15-6 | E12: 4번 case | I12: WPCStatus = NFC_Mode | M12: WPCStatus = WPC_Mode | Q12: 온도센서 에러 On | U12: Off | V12: Off | W12: OK | X12: NFC 사양
B13: WPC(SW)-기능-15-7 | E13: 4번 case | I13: WPCStatus = Off_Mode | M13: WPCStatus = WPC_Mode | Q13: 온도센서 에러 On | U13: Off | V13: Off | W13: OK
B14: WPC(SW)-기능-16-1 | E14: 4번 case | I14: 1번 온도센서 에러 해제 | M14: - | Q14: 온도센서 에러 On | U14: Off | V14: Off | W14: OK
B15: WPC(SW)-기능-16-2 | E15: 윗 case | I15: WPCStatus = NFC_Mode | M15: WPCStatus = WPC_Mode | Q15: 온도센서 에러 Off | U15: On | V15: On | W15: OK | X15: NFC 사양 | AA15: off mode 에서만 동작함
B16: WPC(SW)-기능-16-3 | E16: 8번case | I16: WPCStatus = Off_Mode | M16: WPCStatus = WPC_Mode | Q16: 온도센서 에러 Off | U16: On | V16: On | W16: OK
B17: WPC(SW)-기능-15-8 | E17: WPCStatus = WPCMode | I17: 온도센서 모두 정상 | M17: 2번 온도센서 에러 2s 이상 유지 | Q17: 온도센서 에러 On | U17: Off | V17: Off | W17: N/A
B18: WPC(SW)-기능-15-9 | E18: 11번 case | I18: WPCStatus = NFC_Mode | M18: WPCStatus = WPC_Mode | Q18: 온도센서 에러 On | U18: Off | V18: Off | W18: N/A | X18: NFC 사양
B19: WPC(SW)-기능-15-10 | E19: 11번 case | I19: WPCStatus = Off_Mode | M19: WPCStatus = WPC_Mode | Q19: 온도센서 에러 On | U19: Off | V19: Off | W19: N/A
B20: WPC(SW)-기능-16-4 | E20: 11번 case | I20: 2번 온도센서 에러 해제 | M20: - | Q20: 온도센서 에러 On | U20: Off | V20: Off | W20: N/A
B21: WPC(SW)-기능-16-5 | E21: 윗 case | I21: WPCStatus = NFC_Mode | M21: WPCStatus = WPC_Mode | Q21: 온도센서 에러 Off | U21: On | V21: On | W21: N/A | X21: NFC 사양
B22: WPC(SW)-기능-16-6 | E22: 14번 case | I22: WPCStatus = Off_Mode | M22: WPCStatus = WPC_Mode | Q22: 온도센서 에러 Off | U22: On | V22: On | W22: N/A
B23: WPC(SW)-기능-15-11 | E23: WPCStatus = WPCMode | I23: 온도센서 모두 정상 | M23: 3번 온도센서 에러 2s 이상 유지 | Q23: 온도센서 에러 On | U23: Off | V23: Off | W23: N/A
B24: WPC(SW)-기능-15-12 | E24: 17번 case | I24: WPCStatus = NFC_Mode | M24: WPCStatus = WPC_Mode | Q24: 온도센서 에러 On | U24: Off | V24: Off | W24: N/A | X24: NFC 사양
B25: WPC(SW)-기능-15-13 | E25: 17번 case | I25: WPCStatus = Off_Mode | M25: WPCStatus = WPC_Mode | Q25: 온도센서 에러 On | U25: Off | V25: Off | W25: N/A
B26: WPC(SW)-기능-16-7 | E26: 17번 case | I26: 3번 온도센서 에러 해제 | M26: - | Q26: 온도센서 에러 On | U26: Off | V26: Off | W26: N/A
B27: WPC(SW)-기능-16-8 | E27: 윗 case | I27: WPCStatus = NFC_Mode | M27: WPCStatus = WPC_Mode | Q27: 온도센서 에러 Off | U27: On | V27: On | W27: N/A | X27: NFC 사양
B28: WPC(SW)-기능-16-9 | E28: 20번 case | I28: WPCStatus = Off_Mode | M28: WPCStatus = WPC_Mode | Q28: 온도센서 에러 Off | U28: On | V28: On | W28: N/A
B29: WPC(SW)-기능-15-14 | E29: WPCStatus = WPCMode | I29: 온도센서 모두 정상 | M29: 모든 온도센서 에러 2s 이상 유지 | Q29: 온도센서 에러 On | U29: Off | V29: Off | W29: N/A
B30: WPC(SW)-기능-16-10 | E30: 윗 case | I30: 1번 온도센서 에러 해제 | M30: WPCStatus = NFC_Mode -> WPCMode | Q30: 온도센서 에러 On 유지 | U30: Off | V30: Off | W30: N/A | X30: NFC 사양, 1코일 충전 가능
B31: WPC(SW)-기능-16-11 | E31: 윗 case | I31: 2번 온도센서 에러 해제 | M31: WPCStatus = NFC_Mode -> WPCMode | Q31: 온도센서 에러 On 유지 | U31: Off | V31: Off | W31: N/A | X31: NFC 사양
B32: WPC(SW)-기능-16-12 | E32: 윗 case | I32: 3번 온도센서 에러 해제 | M32: WPCStatus = NFC_Mode -> WPCMode | Q32: 온도센서 에러 Off | U32: On | V32: On | W32: N/A | X32: NFC 사양
B33: WPC(SW)-기능-15-15 | E33: WPCStatus = WPCMode | I33: 온도센서 모두 정상 | M33: 모든 온도센서 에러 2s 이상 유지 | Q33: 온도센서 에러 On | U33: Off | V33: Off | W33: N/A
B34: WPC(SW)-기능-16-13 | E34: 윗 case | I34: 1번 온도센서 에러 해제 | M34: WPCStatus = Off_Mode -> WPCMode | Q34: 온도센서 에러 On 유지 | U34: Off | V34: Off | W34: N/A | X34: NFC 사양, 1코일 충전 가능
B35: WPC(SW)-기능-16-14 | E35: 윗 case | I35: 2번 온도센서 에러 해제 | M35: WPCStatus = Off_Mode -> WPCMode | Q35: 온도센서 에러 On 유지 | U35: Off | V35: Off | W35: N/A
B36: WPC(SW)-기능-16-15 | E36: 윗 case | I36: 3번 온도센서 에러 해제 | M36: WPCStatus = Off_Mode -> WPCMode | Q36: 온도센서 에러 Off | U36: On | V36: On | W36: N/A

Sheet LED Output Control
C2: WPC LED Output Control Function
C4: No | D4: 구분 | F4: 초기 조건 | J4: 평가조건1 | N4: 평가조건2 | R4: 사양 결과 | V4: 충전상태 | W4: LED | X4: 결과 | Y4: 비고 | AC4: 항목 수
AB5: 총 | AC5: =SUM(AC6:AC8) -> 114
B6: IND Output without Detent Control (type 2) | C6: 1 | D6: Rheostat 적용 IntTailOn 전용 | F6: C_IntTailOn == On | J6: 충전 중 | N6: 각 단계별 Rheostat Level 변경 | R6: 각 단계별 LED Duty | V6: On | W6: On | X6: N/A | AB6: OK | AC6: =COUNTIF(X:X,"OK") -> 18
B7: IND Output without Detent Control (type 2) | C7: 2 | F7: C_IntTailOn == On | J7: 충전 완료 | N7: 각 단계별 Rheostat Level 변경 | R7: 각 단계별 LED Duty | V7: On | W7: On | X7: N/A | AB7: NG | AC7: =COUNTIF(X:X,"NG") -> 0
B8: IND Output without Detent Control (type 2) | C8: 3 | F8: C_IntTailOn == On | J8: Error (FOD or 과열) | N8: 각 단계별 Rheostat Level 변경 | R8: 각 단계별 LED Duty | V8: On | W8: On | X8: N/A | AB8: N/A | AC8: =COUNTIF(X:X,"N/A") -> 96
B9: IND Output without Detent Control (type 2) | C9: 4 | F9: C_IntTailOn == On && C_Detentout == On | J9: 충전 중 | N9: 각 단계별 Rheostat Level 변경 | R9: 각 단계별 LED Duty | V9: On | W9: On | X9: N/A | Y9: Detentout 무관
B10: IND Output without Detent Control (type 2) | C10: 5 | F10: C_IntTailOn == On && C_Detentout == On | J10: 충전 완료 | N10: 각 단계별 Rheostat Level 변경 | R10: 각 단계별 LED Duty | V10: On | W10: On | X10: N/A | Y10: Detentout 무관
B11: IND Output without Detent Control (type 2) | C11: 6 | F11: C_IntTailOn == On && C_Detentout == On | J11: Error (FOD or 과열) | N11: 각 단계별 Rheostat Level 변경 | R11: 각 단계별 LED Duty | V11: On | W11: On | X11: N/A | Y11: Detentout 무관
B12: IND Output without Detent Control (type 2) | C12: 7 | F12: C_IntTailOn == Off | J12: 충전 중 | N12: 각 단계별 Rheostat Level 변경 | R12: LED Duty 100% | V12: On | W12: On | X12: N/A
B13: IND Output without Detent Control (type 2) | C13: 8 | F13: C_IntTailOn == Off | J13: 충전 완료 | N13: 각 단계별 Rheostat Level 변경 | R13: LED Duty 100% | V13: On | W13: On | X13: N/A
B14: IND Output without Detent Control (type 2) | C14: 9 | F14: C_IntTailOn == Off | J14: Error (FOD or 과열) | N14: 각 단계별 Rheostat Level 변경 | R14: LED Duty 100% | V14: On | W14: On | X14: N/A
C16: No | D16: 구분 | F16: 초기 조건 | J16: 평가조건1 | N16: 평가조건2 | R16: 사양 결과 | V16: 충전상태 | W16: LED | X16: 결과 | Y16: 비고
B18: IND Output with Detent Control Function (type 1) | C18: 1 | D18: Rheostat 적용 Detentout 전용 | F18: C_Detentout == On | J18: 충전 중 | N18: 각 단계별 Rheostat Level 변경 | R18: LED Duty 100% | V18: On | W18: On | X18: N/A
B19: IND Output with Detent Control Function (type 1) | C19: 2 | F19: C_Detentout == On | J19: 충전 완료 | N19: 각 단계별 Rheostat Level 변경 | R19: LED Duty 100% | V19: On | W19: On | X19: N/A
B20: IND Output with Detent Control Function (type 1) | C20: 3 | F20: C_Detentout == On | J20: Error (FOD or 과열) | N20: 각 단계별 Rheostat Level 변경 | R20: LED Duty 100% | V20: On | W20: On | X20: N/A
B21: IND Output with Detent Control Function (type 1) | C21: 4 | F21: C_Detentout == On && IntTail == On | J21: 충전 중 | N21: 각 단계별 Rheostat Level 변경 | R21: LED Duty 100% | V21: On | W21: On | X21: N/A | Y21: C_IntTailOn 무관
B22: IND Output with Detent Control Function (type 1) | C22: 5 | F22: C_Detentout == On && IntTail == On | J22: 충전 완료 | N22: 각 단계별 Rheostat Level 변경 | R22: LED Duty 100% | V22: On | W22: On | X22: N/A | Y22: C_IntTailOn 무관
B23: IND Output with Detent Control Function (type 1) | C23: 6 | F23: C_Detentout == On && IntTail == On | J23: Error (FOD or 과열) | N23: 각 단계별 Rheostat Level 변경 | R23: LED Duty 100% | V23: On | W23: On | X23: N/A | Y23: C_IntTailOn 무관
B24: IND Output with Detent Control Function (type 1) | C24: 7 | F24: C_Detentout == Off | J24: 충전 중 | N24: 각 단계별 Rheostat Level 변경 | R24: 각 단계별 LED Duty | V24: On | W24: On | X24: N/A
B25: IND Output with Detent Control Function (type 1) | C25: 8 | F25: C_Detentout == Off | J25: 충전 완료 | N25: 각 단계별 Rheostat Level 변경 | R25: 각 단계별 LED Duty | V25: On | W25: On | X25: N/A
B26: IND Output with Detent Control Function (type 1) | C26: 9 | F26: C_Detentout == Off | J26: Error (FOD or 과열) | N26: 각 단계별 Rheostat Level 변경 | R26: 각 단계별 LED Duty | V26: On | W26: On | X26: N/A
C28: No | D28: 구분 | F28: 초기 조건 | J28: 평가조건1 | N28: 평가조건2 | R28: 사양 결과 | V28: 충전상태 | W28: LED | X28: 결과 | Y28: 비고
B30: IND Output with Detent Control Function (type 1) | C30: 1 | D30: Rheostat 적용 YGPE 전용 | F30: C_IntTailOn == On && C_Detentout == On | J30: 충전 중 | N30: 각 단계별 Rheostat Level 변경 | R30: LED Duty 100% | V30: On | W30: On | X30: N/A
B31: IND Output with Detent Control Function (type 1) | C31: 2 | F31: C_IntTailOn == On && C_Detentout == On | J31: 충전 완료 | N31: 각 단계별 Rheostat Level 변경 | R31: LED Duty 100% | V31: On | W31: On | X31: N/A
B32: IND Output with Detent Control Function (type 1) | C32: 3 | F32: C_IntTailOn == On && C_Detentout == On | J32: Error (FOD or 과열) | N32: 각 단계별 Rheostat Level 변경 | R32: LED Duty 100% | V32: On | W32: On | X32: N/A
